Workbook

Sheet H01_PARAMETROS_GENERALES
A1: Sistema de Integridad Algorítmica Preventiva | SIAP-ICPI v1.0
A2: Herramienta de Certificación de Congruencia Programática para Gobiernos Autónomos Descentralizados
A3: GRUPO 1: METADATOS — Parámetros Generales del Sistema
A4: ← H01 (esta hoja) | Navegar a: →
A5: Parámetro | B5: Valor | C5: Descripción | D5: Celda Nombrada
A6: GAD_Nombre | B6: GAD Municipal de Montecristi | C6: Nombre oficial del Gobierno Autónomo Descentralizado | D6: GAD_Nombre
A7: GAD_Provincia | B7: Manabí | C7: Provincia de Ecuador donde opera el GAD | D7: GAD_Provincia
A8: GAD_RUC | B8: 1360029750001 | C8: Registro Único de Contribuyentes del GAD | D8: GAD_RUC
A9: GAD_Poblacion | B9: 50000 | C9: Población cantonal según proyección INEC 2024 | D9: GAD_Poblacion
A10: PDOT_Periodo | B10: 2023-2027 | C10: Período de vigencia del Plan de Desarrollo Territorial | D10: PDOT_Periodo
A11: Año_Fiscal | B11: 2024 | C11: Año fiscal objeto de evaluación ICPI | D11: Año_Fiscal
A12: ICM_OFICIAL | B12: 1 | C12: ICM oficial reportado en SIGAD para año fiscal 2024. Valor real: 1.00 (100%). Fuente: Reporte SIGAD oficial GAD Montecristi, 9 metas ingresadas, $3,939,101.48. NOTA METODOLÓGICA: ICM=100% sobre 41.4% del presupuesto estratégico SIAP activa MOM-I con severidad Alta. | D12: ICM_OFICIAL
A13: Presupuesto_PDOT | B13: 16500000 | C13: Presupuesto total PDOT 2023-2027 en USD | D13: Presupuesto_PDOT
A14: Fecha_Generacion | B14: =TODAY() -> 46110 | C14: Fecha de generación automática del reporte | D14: Fecha_Generacion
A15: Responsable | B15: Ronald Javier Delgado Santana | C15: Responsable técnico del sistema SIAP-ICPI | D15: Responsable
A16: Version_Sistema | B16: SIAP-ICPI v1.0 | C16: Versión del artefacto operativo | D16: Version_Sistema
A17: Plataforma_Comercial | B17: QUADRUM | C17: Nombre comercial de la plataforma GovTech que implementa el SIAP-ICPI. QUADRUM es la marca para presentación ante GADs, organismos bilaterales y el DGIP CAF-ESPOL. | D17: Plataforma_Comercial
A18: Moneda | B18: USD | C18: Moneda de referencia del sistema presupuestario | D18: Moneda
A19: Coef_CurvaS | B19: 0.5 | C19: Coeficiente logístico para Curva S de monitoreo (H20) | D19: Coef_CurvaS
A20: Inflexion_CurvaS | B20: 6 | C20: Punto de inflexión de la Curva S (mes 1-12) | D20: Inflexion_CurvaS
A22: PANEL DE VERIFICACIONES AUTOMÁTICAS — Semáforo del Sistema
A23: Verificación | B23: Estado | C23: Valor Actual | D23: Umbral
A24: Suma P_i = 1.000 | B24: =IF(ABS(H05_METAS_PDOT!H23-1)<0.0001,"✅ CORRECTO","❌ ERROR") -> ❌ ERROR | C24: =H05_METAS_PDOT!H23 -> 0.022309711 | D24: 1
A25: ICPI en rango 0-100% | B25: =IF(AND(H14_CALCULO_ICPI!C5>=0,H14_CALCULO_ICPI!C5<=100),"✅ CORRECTO","❌ ERROR") -> ❌ ERROR | C25: =H14_CALCULO_ICPI!C5&"%" -> R_i% | D25: 0% - 100%
A26: Sin errores DIV/0 | B26: ✅ Verificado al generar | C26: OK | D26: Sin errores
A27: Sin errores REF | B27: ✅ Verificado al generar | C27: OK | D27: Sin errores
A28: ICM en rango válido (0–1) | B28: =IF(AND(B12>0,B12<=1),"✅ ICM en rango válido","❌ Revisar rango 0-1") -> ✅ ICM en rango válido | C28: =B12&" (92% — rango válido: >0 y ≤1)" -> 1 (92% — rango válido: >0 y ≤1) | D28: 0 < ICM ≤ 1
A29: Metas certificadas (V_i=1) | B29: =COUNTIF(H14_CALCULO_ICPI!J2:J21,1)&" de 20" -> 12 de 20 | C29: =COUNTIF(H14_CALCULO_ICPI!J2:J21,1) -> 12 | D29: 20 (ideal)
A30: PDOT período correcto | B30: =IF(ISNUMBER(SEARCH("2023",B10)),"✅ 2023-2027 confirmado","⚠️ Verificar período PDOT") -> ✅ 2023-2027 confirmado | C30: =B10 -> 2023-2027 | D30: 2023-2027
A31: Versión del sistema | B31: ="ℹ️ Versión activa: "&B16 -> ℹ️ Versión activa: SIAP-ICPI v1.0 | C31: =B16 -> SIAP-ICPI v1.0 | D31: SIAP-ICPI v1.0
A32: Silo SIGAD presente (H10B) | B32: =IFERROR(IF(H10B_DATOS_SIGAD!B19>0,"✅ Silo SIGAD presente — ICM="&TEXT(H10B_DATOS_SIGAD!F19,"0%")&" | $"&TEXT(H10B_DATOS_SIGAD!D19,"#,##0")&" | "&TEXT(H10B_DATOS_SIGAD!I19,"0.0%")&" represent.","❌ Silo SIGAD no cargado"),"❌ H10B_DATOS_SIGAD no encontrada") -> ✅ Silo SIGAD presente — ICM=100% | $3939101,480 | 41% represent. | C32: ="Metas SIGAD: "&H10B_DATOS_SIGAD!B19&" | Represent. presup.: "&TEXT(H10B_DATOS_SIGAD!I19,"0.0%") -> Metas SIGAD: 9 | Represent. presup.: 41% | D32: H10B_DATOS_SIGAD
A33: Silo CNE presente (H04B) | B33: =IFERROR(IF(H04B_DATOS_CNE!B52>0,"✅ Silo CNE presente — IFE="&TEXT(H04B_DATOS_CNE!B52,"0.0")&"% | 20 promesas verificadas","❌ Silo CNE no cargado"),"❌ H04B_DATOS_CNE no encontrada") -> ✅ Silo CNE presente — IFE=98% | 20 promesas verificadas | C33: ="IFE Global: "&TEXT(H04B_DATOS_CNE!B52,"0.0")&"% | 5 ejes verificados" -> IFE Global: 98% | 5 ejes verificados | D33: H04B_DATOS_CNE
A35: ÍNDICE DE NAVEGACIÓN — 26 Hojas del Sistema SIAP-ICPI
A36: Grupo | B36: Hoja | C36: Descripción | D36: Acceso
A37: G1 — Metadatos | B37: H01_PARAMETROS_GENERALES | C37: Parámetros, verificaciones e índice del sistema | D37: Esta hoja
A38: G1 — Metadatos | B38: H02_GLOSARIO_TECNICO | C38: 28+ términos metodológicos y legales | D38: → H02
A39: G1 — Metadatos | B39: H03_CONTROL_VERSIONES | C39: Historial de versiones del artefacto | D39: → H03
A40: G2 — Silos de Datos | B40: H04_TABLAS_PARAMETRICAS | C40: 7 tablas maestras con rangos nombrados | D40: → H04
A41: G2 — Silos de Datos | B41: H05_METAS_PDOT | C41: BASE SUSTANCIAL: 20 metas PDOT 2023-2027 | D41: → H05
A42: G2 — Silos de Datos | B42: H06_VINCULACIONES_POA | C42: Vinculación meta PDOT ↔ proyecto POA | D42: → H06
...

Sheet H02_GLOSARIO_TECNICO
A1: 🔙 Volver al Índice
A2: H02 — GLOSARIO TÉCNICO: Términos metodológicos, operativos y legales del sistema SIAP-ICPI
A3: ← H01
A5: Término | B5: Definición | C5: Referencia Legal / Metodológica | D5: Categoría
A6: SIAP | B6: Sistema de Integridad Algorítmica Preventiva. Marco metodológico que verifica la congruencia entre planificación, ejecución presupuestaria y evidencia documental de los GADs. | C6: Metodología propia SIAP-ICPI v1.0 | D6: Sistema
A7: ICPI | B7: Índice de Congruencia Programática e Intersistémica. Indicador sintético (0-100%) que mide la trazabilidad del ciclo planificación-ejecución-transparencia de las metas PDOT. | C7: Fórmula: Σ(Pi×Ri×Vi×Ei×Ti×Ci) / Σ(Pi×Ri) × 100 | D7: Índice
A8: CININ | B8: Ciclo de Integridad Normativa e Institucional. Secuencia metodológica que atraviesa los 5 silos de información: POA → SERCOP → eSIGEF → LOTAIP → CPCCS. | C8: SIAP-ICPI v1.0 §2.1 | D8: Metodología
A9: PDOT | B9: Plan de Desarrollo y Ordenamiento Territorial. Instrumento de planificación de mediano plazo de los GADs. BASE SUSTANCIAL del SIAP-ICPI. Sin PDOT no existe sistema. | C9: COOTAD Art. 295-296; SENPLADES 2019 | D9: Planificación
A10: POA | B10: Plan Operativo Anual. Instrumento de planificación que operativiza el PDOT para cada año fiscal. Primer silo del CININ. | C10: COOTAD Art. 234; COPYFP Art. 97 | D10: Planificación
A11: V_i | B11: Variable de Trazabilidad de la meta i. Valor binario (0/1) que indica si la meta cumple el umbral mínimo de silos requeridos según su fuente de financiamiento. V_i MALEABLE según fuente. | C11: SIAP-ICPI v1.0 §3.2 | D11: Cálculo
A12: P_i | B12: Peso presupuestario de la meta i. P_i = Presupuesto_Anual_i / Presupuesto_Total_PDOT_Anual. Suma de todos los P_i = 1.0000 exacto. | C12: SIAP-ICPI v1.0 §3.1 | D12: Cálculo
A13: R_i | B13: Factor de Relevancia Competencial. Ponderación según tipo de competencia COOTAD: 1.5 (exclusiva), 1.0 (adicional), 0.5 (concurrente). | C13: COOTAD Art. 55, 64, 65 | D13: Cálculo
A14: T_i | B14: Tasa de Ejecución Presupuestaria. T_i = Devengado_Total / Codificado_Vigente. Fuente: eSIGEF. Rango [0,1]. | C14: e-SIGEF Ministerio de Finanzas Ecuador | D14: Cálculo
A15: E_i | B15: Factor de Eficiencia de Modalidad. Escala: Directa GAD=1.00, Compartida=0.90, Delegada EP=0.75. Refleja autonomía de gestión del GAD. | C15: COOTAD Art. 126-130 | D15: Cálculo
A16: C_i | B16: Factor de Claridad Orgánica. Escala: Única=1.00, Compartida=0.90, Difusa=0.75. Refleja precisión en atribución institucional de la meta. | C16: Estatuto Orgánico del GAD (H12) | D16: Cálculo
... A37: QUADRUM | B37: Nombre comercial de la plataforma GovTech que implementa el motor metodológico SIAP-ICPI para su uso por GADs municipales y organismos bilaterales. QUADRUM integra el cálculo del ICPI, los protocolos MOM y el módulo ciudadano TAC en una interfaz operativa. Relación: QUADRUM implementa SIAP-ICPI y comunica sus resultados a través de TAC. El artefacto Excel es el PMV v1.0 de QUADRUM. | C37: Ordenanza Municipal Alfaro Virtus.0 | D37: Plataforma

Sheet H03_CONTROL_VERSIONES
A1: 🔙 Volver al Índice
A2: H03 — CONTROL DE VERSIONES: Historial de evolución del artefacto operativo SIAP-ICPI
A3: ← H01
A5: Versión | B5: Fecha | C5: Descripción de Cambios | D5: Responsable | E5: Estado
A6: v0.1 — Prototipo Conceptual | B6: 15/03/2024 | C6: Diseño inicial de la arquitectura del sistema: definición de los 5 silos de información (POA, SERCOP, eSIGEF, LOTAIP, CPCCS), fórmula ICPI base, escala AVEP preliminar. Sin datos de GAD. | D6: Ronald J. Delgado S. | E6: Archivado
A7: v0.8 — Prueba de Concepto | B7: 30/08/2024 | C7: Incorporación de los Protocolos MOM (I, II, III) como señales de atención temprana. Desarrollo del V_i Maleable según fuente de financiamiento. Integración del IFE con Plan CNE. Primera versión con datos simulados del GAD Montecristi. Validación de la fórmula ICPI con 20 metas. | D7: Ronald J. Delgado S. | E7: Archivado
A8: v1.0 — Producto Mínimo Viable | B8: =TODAY() -> 46110 | C8: Artefacto operativo completo: 33 hojas — Motor Central (H01-H26) + Módulo de Salidas Institucionales (H27-H31). 797 fórmulas activas. 8 silos de información pública integrados. 0 errores de fórmula. | D8: Ronald J. Delgado S. | E8: ✅ ACTIVO
A10: NOTA METODOLÓGICA:
A11: Este artefacto sirve como Producto Mínimo Viable (PMV) del sistema SIAP-ICPI. Los datos de referencia del GAD Municipal de Montecristi son ficticios-coherentes y pueden sustituirse por datos reales de cualquier GAD de América Latina. La arquitectura del sistema es neutral, reutilizable y adaptable a cualquier jurisdicción que opere con planificación territorial (PDOT o equivalente) y sistemas de contratación pública y presupuesto electrónico.

Sheet H04_TABLAS_PARAMETRICAS
A1: 🔙 Volver al Índice
A2: H04 — TABLAS PARAMÉTRICAS: 7 tablas maestras con rangos nombrados para validación de datos y listas desplegables
A3: ← H01
A5: TABLA 1 — EJES_ESTRATEGICOS | E5: TABLA 2 — COMPETENCIAS_COOTAD
A6: ID_Eje | B6: Nombre_Eje | C6: Descripcion | E6: ID | F6: Nombre | G6: R_i | H6: Art_Legal
A7: AS | B7: Ambiental Sostenible | C7: Gestión ambiental, recursos naturales y saneamiento | E7: AGUA | F7: Agua Potable | G7: 1.5 | H7: COOTAD Art.55(d)
A8: EC | B8: Económico Productivo | C8: Desarrollo económico local y fomento productivo | E8: ALCA | F8: Alcantarillado | G8: 1.5 | H8: COOTAD Art.55(d)
A9: SC | B9: Social e Inclusivo | C9: Servicios sociales, salud, educación y bienestar | E9: DESO | F9: Desechos Sólidos | G9: 1.5 | H9: COOTAD Art.55(d)
A10: OT | B10: Ordenamiento Territorial | C10: Vialidad, infraestructura física y uso de suelo | E10: AMBI | F10: Gestión Ambiental | G10: 1.5 | H10: COOTAD Art.55(d)
A11: PI | B11: Político Institucional | C11: Gobernanza, transparencia y fortalecimiento institucional | E11: VIAL | F11: Vialidad Urbana | G11: 1 | H11: COOTAD Art.55(a)
E12: ORTE | F12: Ordenamiento Territ. | G12: 1 | H12: COOTAD Art.55(b)
E13: EQUI | F13: Equipamiento Salud/Edu | G13: 1 | H13: COOTAD Art.55(g)
E14: TRAN | F14: Tránsito y Transporte | G14: 1 | H14: COOTAD Art.55(f)
E15: CULT | F15: Cultura y Patrimonio | G15: 0.5 | H15: COOTAD Art.55(h)
E16: DEPO | F16: Deporte y Recreación | G16: 0.5 | H16: COOTAD Art.55(h)
E17: TURI | F17: Turismo | G17: 0.5 | H17: COOTAD Art.55(q)
E18: INST | F18: Fortalecimiento Inst. | G18: 0.5 | H18: COOTAD Art.54
A21: TABLA 3 — ESTADOS_SERCOP | E21: TABLA 4 — MODALIDADES_EJECUCION
A22: ID | B22: Estado | C22: Valido_Vi | E22: ID | F22: Modalidad | G22: E_i | H22: Descripcion
A23: ADJ | B23: Adjudicado | C23: 1 | E23: DIR | F23: Directa GAD | G23: 1 | H23: Dirección propia del GAD ejecuta el proceso
A24: FIN | B24: Finalizado | C24: 1 | E24: COM | F24: Compartida | G24: 0.9 | H24: Convenio interinstitucional o compartida con otro nivel
A25: EJE | B25: En Ejecución | C25: 1 | E25: DEL | F25: Delegada EP | G25: 0.75 | H25: Empresa pública, patronato u organismo delegado
A26: DES | B26: Desierto | C26: 0
A27: CAN | B27: Cancelado | C27: 0
A28: SUS | B28: Suspendido | C28: 0
A31: TABLA 5 — TIPOS_RESPONSABILIDAD | E31: TABLA 6 — FUENTES_FINANCIAMIENTO y V_i MALEABLE
A32: ID | B32: Tipo | C32: C_i | E32: ID | F32: Fuente | G32: Silos_Vi_Requeridos | H32: Descripcion
A33: UNI | B33: Única | C33: 1 | E33: GAD | F33: Recursos propios GAD | G33: 5 silos AND completo | H33: POA ∧ SERCOP ∧ eSIGEF ∧ LOTAIP ∧ CPCCS
A34: CPT | B34: Compartida | C34: 0.9 | E34: COO | F34: Cooperación internacional | G34: 4 silos (sin CPCCS) | H34: POA ∧ SERCOP ∧ eSIGEF ∧ LOTAIP
A35: DIF | B35: Difusa | C35: 0.75 | E35: SFP | F35: Sin financiamiento propio | G35: 3 silos mínimo | H35: POA ∧ SERCOP ∧ eSIGEF
A38: TABLA 7 — ODS_CLUSTERS
A39: ID | B39: ODS_Relacionados | C39: Descripcion
A40: Inclusion | B40: ODS 1, 2, 3, 4, 5, 10 | C40: Servicios sociales, salud, educación, equidad
A41: Infraestructura | B41: ODS 6, 7, 9, 11, 13 | C41: Agua, energía, obras, ciudad, clima
A42: Gobernanza | B42: ODS 16, 17 | C42: Instituciones, transparencia, alianzas estratégicas

Sheet H04B_DATOS_CNE
A1: 🔙 Volver al Índice
A2: H04B_DATOS_CNE — SILO 0: Plan de Trabajo Electoral CNE | Fuente: Plan Trabajo Alcalde Luis Jonathan Toro Largacha, Elecciones Seccionales 2023, Período 2023-2027
A3: ← H01 | El Plan CNE es INSUMO COMPARATIVO del IFE (§3.7.1). Sin CNE hay ICPI pero no IFE. CNE ≠ base operativa del sistema. La base operativa siempre es el PDOT.
A5: A · IDENTIFICACIÓN DEL PLAN DE TRABAJO CNE
A6: Parámetro | B6: Valor
A7: Candidato | B7: Luis Jonathan Toro Largacha
A8: Partido | B8: AVANZA Lista 8 + MACHETE Lista 61
A9: Dignidad | B9: Alcalde del Cantón Montecristi
A10: Elecciones | B10: Seccionales 2023
A11: Período | B11: 2023-2027
A12: Población | B12: 116,186 habitantes (INEC proyección 2022)
A13: Ejes_Plan | B13: 5 (Económico, Institucional, Social, Ambiental, Territorial)
A14: Total_Promesas_CNE | B14: 20
A15: ODS_Vinculados | B15: ODS 1,2,3,4,5,6,7,8,9,10,11,13,16,17
A16: Registro_CNE | B16: Plan Trabajo Electoral CNE — Expediente Elecciones Seccionales 2023
A18: B · PROMESAS CNE — MATRIZ PLURIANUAL POR EJE (§3.7.1)
A19: Esta tabla es la FUENTE del IFE. Cada promesa se vincula a una meta PDOT para calcular el score V_j. Score 1.0 = verde, 0.5 = amarillo, 0.0 = rojo.
A20: ID_Promesa | B20: Eje_CNE | C20: Objetivo_Especifico_CNE | D20: Meta_Promesa_CNE | E20: Competencia_Vinculada | F20: ODS_Relacionados | G20: Año1 | H20: Año2 | I20: Año3 | J20: Año4 | K20: ID_Meta_PDOT | L20: Tipo_Vinculacion | M20: Score_IFE | N20: Justificacion_Vinculacion
A21: EJE ECONÓMICO
A22: EC-001 | B22: Económico | C22: Obj 16: Procesar carne fresca alta calidad | D22: Desarrollar capacidades productivas y comerciales del sector artesanal y agropecuario | E22: Turismo-Desarrollo Económico | F22: ODS 8, 9 | G22: 2023 | H22: 2024 | I22: 2025 | J22: 2026 | K22: PDOT-013 | L22: Alta | M22: 1 | N22: Capacitación artesanos sombrero paja toquilla — correspondencia directa
A23: EC-002 | B23: Económico | C23: Obj 6: TICs para trámites ciudadanos | D23: Implementar plataforma digital de servicios municipales | E23: Fortalecimiento Institucional | F23: ODS 9, 16 | G23: 2023 | H23: 2024 | I23: 2025 | J23: 2026 | K23: PDOT-019 | L23: Alta | M23: 1 | N23: Modernización sistema recaudación — tecnología municipal
A24: EC-003 | B24: Económico | C24: Alianzas sector privado | D24: Gestionar 28 convenios de cooperación para fortalecimiento institucional | E24: Cooperación Internacional | F24: ODS 17 | G24: 2023 | H24: 2024 | I24: 2025 | J24: 2026 | K24: PDOT-013 | L24: Alta | M24: 1 | N24: 28 convenios coinciden exactamente con meta SIGAD-001
A25: EC-004 | B25: Económico | C25: Turismo sostenible | D25: Rehabilitar malecón costero para fomento turístico | E25: Turismo | F25: ODS 8, 11 | G25: 2023 | H25: 2024 | I25: 2025 | J25: 2026 | K25: PDOT-011 | L25: Alta | M25: 1 | N25: Malecón costero Montecristi — identificación directa
A26: EC-005 | B26: Económico | C26: Mercado y comercio local | D26: Rehabilitar y modernizar mercado municipal | E26: Ordenamiento Territorial | F26: ODS 11 | G26: 2023 | H26: 2024 | I26: 2025 | J26: 2026 | K26: PDOT-005 | L26: Alta | M26: 1 | N26: Rehabilitación mercado municipal — meta directa
A27: EJE INSTITUCIONAL
A28: IN-001 | B28: Institucional | C28: Obj 12: Participación ciudadana | D28: Crear espacios de participación para informar sobre recursos públicos | E28: Fortalecimiento Institucional | F28: ODS 16 | G28: 2023 | H28: 2024 | I28: 2025 | J28: 2026 | K28: PDOT-015 | L28: Alta | M28: 1 | N28: Transparencia municipal LOTAIP — correspondencia directa
A29: IN-002 | B29: Institucional | C29: Obj: Rendición de cuentas | D29: Mecanismos periódicos y públicos de rendición de cuentas | E29: Fortalecimiento Institucional | F29: ODS 16, 17 | G29: 2023 | H29: 2024 | I29: 2025 | J29: 2026 | K29: PDOT-015 | L29: Alta | M29: 1 | N29: Fortalecimiento transparencia — objetivo idéntico
A30: IN-003 | B30: Institucional | C30: Ordenamiento territorial | D30: Modernizar el sistema de catastro predial para planificación | E30: Ordenamiento Territorial | F30: ODS 11, 16 | G30: 2023 | H30: 2024 | I30: 2025 | J30: 2026 | K30: PDOT-014 | L30: Alta | M30: 1 | N30: Catastro predial — meta idéntica
A31: IN-004 | B31: Institucional | C31: Recursos municipales | D31: Modernizar sistema de recaudación y gestión financiera | E31: Fortalecimiento Institucional | F31: ODS 16 | G31: 2023 | H31: 2024 | I31: 2025 | J31: 2026 | K31: PDOT-019 | L31: Alta | M31: 1 | N31: Modernización recaudación — correspondencia directa
A32: EJE SOCIAL
A33: SC-001 | B33: Social | C33: Educación | D33: Equipar establecimientos educativos rurales y mejorar infraestructura | E33: Equipamiento Salud/Educación | F33: ODS 4 | G33: 2023 | H33: 2024 | I33: 2025 | J33: 2026 | K33: PDOT-007 | L33: Alta | M33: 1 | N33: Equipamiento educativo establecimientos rurales — meta idéntica
A34: SC-002 | B34: Social | C34: Salud | D34: Construir centro de salud en parroquia rural Aníbal San Andrés | E34: Equipamiento Salud/Educación | F34: ODS 3 | G34: 2023 | H34: 2024 | I34: 2025 | J34: 2026 | K34: PDOT-006 | L34: Alta | M34: 1 | N34: Centro salud tipo C — correspondencia directa
A35: SC-003 | B35: Social | C35: Obj 13: Espacios recreativos | D35: Brindar espacios de entretenimiento en parroquias del cantón | E35: Deporte y Recreación | F35: ODS 3, 11 | G35: 2023 | H35: 2024 | I35: 2025 | J35: 2026 | K35: PDOT-010 | L35: Alta | M35: 1 | N35: Parque recreativo sector norte — meta coincidente
A36: SC-004 | B36: Social | C36: Servicios sociales | D36: Guardería comunitaria para madres trabajadoras | E36: Equipamiento Salud/Educación | F36: ODS 1, 5 | G36: 2023 | H36: 2024 | I36: 2025 | J36: 2026 | K36: PDOT-008 | L36: Alta | M36: 1 | N36: Guardería El Carmen — correspondencia directa
A37: SC-005 | B37: Social | C37: Adultos mayores y discapacidad | D37: Programa de atención a grupos vulnerables: adultos mayores y discapacidad | E37: Servicios Sociales | F37: ODS 1, 3, 10 | G37: 2023 | H37: 2024 | I37: 2025 | J37: 2026 | K37: PDOT-018 | L37: Alta | M37: 1 | N37: Programa adulto mayor y discapacidad — meta idéntica
A38: EJE AMBIENTAL
A39: AM-001 | B39: Ambiental | C39: Agua y saneamiento | D39: Mejorar abastecimiento agua potable sectores rurales | E39: Agua Potable | F39: ODS 6 | G39: 2023 | H39: 2024 | I39: 2025 | J39: 2026 | K39: PDOT-001 | L39: Alta | M39: 1 | N39: Sistema agua potable zonas rurales — correspondencia directa
A40: AM-002 | B40: Ambiental | C40: Alcantarillado y aguas residuales | D40: Ampliar red alcantarillado y tratar aguas residuales | E40: Alcantarillado | F40: ODS 6 | G40: 2023 | H40: 2024 | I40: 2025 | J40: 2026 | K40: PDOT-002 | L40: Alta | M40: 1 | N40: Alcantarillado sanitario + planta tratamiento — metas idénticas
A41: AM-003 | B41: Ambiental | C41: Obj 19: Control ambiental | D41: Reforestar cuencas hídricas y proteger recursos naturales | E41: Gestión Ambiental | F41: ODS 13, 15 | G41: 2023 | H41: 2024 | I41: 2025 | J41: 2026 | K41: PDOT-016 | L41: Alta | M41: 1 | N41: Reforestación cuencas híricas — correspondencia directa
A42: EJE TERRITORIAL
...

Sheet H05_METAS_PDOT
A1: 🔙 Volver al Índice
A2: H05 — METAS PDOT 2023-2027: BASE SUSTANCIAL Y OPERATIVA del sistema. 20 metas del plan de desarrollo territorial del GAD Municipal de Montecristi
A3: ← H01 | Sin PDOT no existe sistema SIAP-ICPI. Este es el universo de análisis.
A5: ⚠️ DATOS DE REFERENCIA — Este artefacto contiene datos ficticios coherentes para demostración metodológica del SIAP-ICPI. Para implementación real: reemplazar con datos del PDOT vigente del GAD. Los datos reales del GAD Montecristi 2024 se cargarán en el Artefacto B para el Diplomado CAF-ESPOL (DGIP 2026).
A6: ID_Meta | B6: Descripcion_Meta | C6: Eje_ID | D6: Competencia_ID | E6: R_i | F6: Presup_Codif_PDOT | G6: Presup_Anual_2024 | H6: P_i | I6: Fuente_Financ | J6: Meta_Cuantitativa | K6: Unidad_Medida | L6: Linea_Base | M6: Indicador_PDOT | N6: Responsable_Direccion | O6: ODS_Cluster | P6: Pag_PDOT | Q6: Nivel_Estres | R6: Nota_Metodologica
A7: PDOT-001 | B7: Construcción sistema agua potable zonas rurales | C7: AS | D7: AGUA | E7: 1.5 | F7: 8500000 | G7: 2125000 | H7: =G7/SUM($G$7:$G$26) -> 0.22309711 | I7: GAD | J7: 45 | K7: Km red | L7: 12 | M7: Km red construida | N7: Dir. Obras Públicas | O7: Infraestructura | P7: 42 | Q7: Nivel2 | R7: Nivel2: ejecutó pero no publicó evidencia LOTAIP completa
A8: PDOT-002 | B8: Ampliación red alcantarillado sanitario | C8: AS | D8: ALCA | E8: 1.5 | F8: 6200000 | G8: 1550000 | H8: =G8/SUM($G$7:$G$26) -> 0.16272966 | I8: GAD | J8: 28 | K8: Km red | L8: 8 | M8: Km alcantarillado ampliado | N8: Dir. Obras Públicas | O8: Infraestructura | P8: 45 | Q8: Nivel3 | R8: Nivel3: proceso SERCOP desierto, devengado mínimo
A9: PDOT-003 | B9: Sistema manejo integral desechos sólidos | C9: AS | D9: DESO | E9: 1.5 | F9: 1800000 | G9: 450000 | H9: =G9/SUM($G$7:$G$26) -> 0.047244094 | I9: DEL | J9: 1 | K9: Sistema | L9: 0 | M9: Sistema operativo | N9: EP Aseo | O9: Infraestructura | P9: 48 | Q9: Nivel3 | R9: Nivel3: proceso SERCOP cancelado, devengado nulo
A10: PDOT-004 | B10: Mejoramiento vialidad urbana cantonal | C10: OT | D10: VIAL | E10: 1 | F10: 3200000 | G10: 800000 | H10: =G10/SUM($G$7:$G$26) -> 0.083989501 | I10: GAD | J10: 18 | K10: Km | L10: 5 | M10: Km vías mejoradas | N10: Dir. Obras Públicas | O10: Infraestructura | P10: 52 | Q10: Nivel1 | R10: Nivel1: trazabilidad plena, modelo de referencia
A11: PDOT-005 | B11: Construcción y rehabilitación mercado municipal | C11: EC | D11: ORTE | E11: 1 | F11: 1500000 | G11: 375000 | H11: =G11/SUM($G$7:$G$26) -> 0.039370079 | I11: GAD | J11: 1 | K11: Mercado | L11: 0 | M11: Mercado rehabilitado | N11: Dir. Gestión Social | O11: Gobernanza | P11: 55 | Q11: Nivel2 | R11: Nivel2: enlace LOTAIP roto (404), ejecutó sin publicar
A12: PDOT-006 | B12: Centro salud tipo C parroquia Aníbal San Andrés | C12: SC | D12: EQUI | E12: 1 | F12: 2800000 | G12: 700000 | H12: =G12/SUM($G$7:$G$26) -> 0.073490814 | I12: COO | J12: 1 | K12: Centro | L12: 0 | M12: Centro construido | N12: Dir. Planificación | O12: Inclusion | P12: 58 | Q12: Nivel3 | R12: Nivel3: proceso desierto; revisar posible MOM-II
A13: PDOT-007 | B13: Equipamiento educativo establecimientos rurales | C13: SC | D13: EQUI | E13: 1 | F13: 950000 | G13: 237500 | H13: =G13/SUM($G$7:$G$26) -> 0.024934383 | I13: COO | J13: 12 | K13: Establec. | L13: 3 | M13: Establec. equipados | N13: Dir. Planificación | O13: Inclusion | P13: 61 | Q13: Nivel2 | R13: Nivel2: contrato accesible, falta acta recepción LOTAIP
A14: PDOT-008 | B14: Guardería municipal comunitaria El Carmen | C14: SC | D14: EQUI | E14: 1 | F14: 1200000 | G14: 300000 | H14: =G14/SUM($G$7:$G$26) -> 0.031496063 | I14: GAD | J14: 1 | K14: Guardería | L14: 0 | M14: Guardería operativa | N14: Dir. Social | O14: Inclusion | P14: 64 | Q14: Nivel3 | R14: Nivel3: proceso cancelado, devengado nulo
A15: PDOT-009 | B15: Sistema drenaje pluvial casco urbano | C15: OT | D15: ALCA | E15: 1.5 | F15: 2100000 | G15: 525000 | H15: =G15/SUM($G$7:$G$26) -> 0.05511811 | I15: GAD | J15: 12 | K15: Km | L15: 0 | M15: Km drenaje construido | N15: Dir. Obras Públicas | O15: Infraestructura | P15: 67 | Q15: Nivel3 | R15: Nivel3: proceso desierto, baja ejecución
A16: PDOT-010 | B16: Parque recreativo y deportivo sector norte | C16: SC | D16: DEPO | E16: 0.5 | F16: 450000 | G16: 112500 | H16: =G16/SUM($G$7:$G$26) -> 0.011811024 | I16: GAD | J16: 1 | K16: Parque | L16: 0 | M16: Parque construido | N16: Dir. Cultura | O16: Inclusion | P16: 70 | Q16: Nivel1 | R16: Nivel1: trazabilidad plena, meta modelo
A17: PDOT-011 | B17: Rehabilitación Malecón costero Montecristi | C17: EC | D17: TURI | E17: 0.5 | F17: 1800000 | G17: 450000 | H17: =G17/SUM($G$7:$G$26) -> 0.047244094 | I17: COM | J17: 1 | K17: Malecón | L17: 0 | M17: Malecón rehabilitado | N17: Dir. Turismo | O17: Infraestructura | P17: 73 | Q17: Nivel2 | R17: Nivel2: en ejecución, documentación parcial
A18: PDOT-012 | B18: Unidad móvil de salud comunitaria | C18: SC | D18: EQUI | E18: 1 | F18: 380000 | G18: 95000 | H18: =G18/SUM($G$7:$G$26) -> 0.0099737533 | I18: GAD | J18: 1 | K18: Unidad | L18: 0 | M18: Unidad operativa | N18: Patronato | O18: Inclusion | P18: 76 | Q18: Nivel4 | R18: Nivel4: MOM-III activo — 8295% declarado vs 8% ejecutado
... A26: PDOT-020 | B26: Planta tratamiento aguas residuales | C26: AS | D26: ALCA | E26: 1.5 | F26: 4200000 | G26: 1050000 | H26: =G26/SUM($G$7:$G$26) -> 0.11023622 | I26: COO | J26: 1 | K26: Planta | L26: 0 | M26: Planta operativa | N26: Dir. Obras Públicas | O26: Infraestructura | P26: 100 | Q26: Nivel3 | R26: Nivel3: proceso existe, sin devengado al 31 dic
G27: VERIFICACIÓN: | H27: =SUM(H7:H26) -> 1 | I27: =IF(ABS(H27-1)<0.0001,"✅ Suma P_i = 1.0000 — CORRECTO","❌ ERROR: Suma ≠ 1") -> ✅ Suma P_i = 1.0000 — CORRECTO

Sheet H06_VINCULACIONES_POA
A1: 🔙 Volver al Índice
A2: H06 — VINCULACIONES POA: Conecta cada meta PDOT con su proyecto en el Plan Operativo Anual. Primer silo del CININ.
A3: ← H01
A5: ID_Vinc | B5: ID_Meta | C5: Codigo_POA | D5: Descripcion_POA | E5: Fecha_Aprobacion_POA | F5: Presupuesto_POA | G5: Responsable_POA | H5: Confianza_Vinculacion | I5: V_POA
A6: VNC-001 | B6: PDOT-001 | C6: AS-AGUA-001 | D6: Acueducto rural — acceso agua potable 8 comunidades | E6: 15/01/2024 | F6: 2125000 | G6: Dir. Obras Públicas | H6: Alta | I6: 1
A7: VNC-002 | B7: PDOT-002 | C7: AS-ALCA-002 | D7: Ampliación red alcantarillado urbano-rural | E7: 15/01/2024 | F7: 1550000 | G7: Dir. Obras Públicas | H7: Alta | I7: 1
A8: VNC-003 | B8: PDOT-003 | C8: AS-DESO-003 | D8: Sistema manejo desechos sólidos delegado EP Aseo | E8: 15/01/2024 | F8: 450000 | G8: EP Aseo | H8: Alta | I8: 1
A9: VNC-004 | B9: PDOT-004 | C9: OT-VIAL-004 | D9: Mejoramiento vías principales urbanas | E9: 15/01/2024 | F9: 800000 | G9: Dir. Obras Públicas | H9: Alta | I9: 1
A10: VNC-005 | B10: PDOT-005 | C10: EC-ORTE-005 | D10: Rehabilitación y equipamiento mercado municipal | E10: 15/01/2024 | F10: 375000 | G10: Dir. Gestión Social | H10: Alta | I10: 1
A11: VNC-006 | B11: PDOT-006 | C11: SC-EQUI-006 | D11: Construcción centro salud tipo C parroquia | E11: 15/01/2024 | F11: 700000 | G11: Dir. Planificación | H11: Alta | I11: 1
A12: VNC-007 | B12: PDOT-007 | C12: SC-EQUI-007 | D12: Equipamiento tecnológico establecimientos educativos rurales | E12: 15/01/2024 | F12: 237500 | G12: Dir. Planificación | H12: Alta | I12: 1
A13: VNC-008 | B13: PDOT-008 | C13: SC-EQUI-008 | D13: Construcción guardería comunitaria El Carmen | E13: 15/01/2024 | F13: 300000 | G13: Dir. Social | H13: Alta | I13: 1
A14: VNC-009 | B14: PDOT-009 | C14: OT-ALCA-009 | D14: Sistema drenaje pluvial casco urbano | E14: 15/01/2024 | F14: 525000 | G14: Dir. Obras Públicas | H14: Alta | I14: 1
A15: VNC-010 | B15: PDOT-010 | C15: SC-DEPO-010 | D15: Construcción parque deportivo sector norte | E15: 15/01/2024 | F15: 112500 | G15: Dir. Cultura | H15: Alta | I15: 1
A16: VNC-011 | B16: PDOT-011 | C16: EC-TURI-011 | D16: Rehabilitación malecón turístico costero | E16: 15/01/2024 | F16: 450000 | G16: Dir. Turismo | H16: Alta | I16: 1
A17: VNC-012 | B17: PDOT-012 | C17: SC-EQUI-012 | D17: Adquisición unidad móvil atención salud | E17: 15/01/2024 | F17: 95000 | G17: Patronato | H17: Alta | I17: 1
... A25: VNC-020 | B25: PDOT-020 | C25: AS-ALCA-020 | D25: Construcción planta tratamiento aguas residuales | E25: 15/01/2024 | F25: 1050000 | G25: Dir. Obras Públicas | H25: Alta | I25: 1

Sheet H07_PROCESOS_SERCOP
A1: 🔙 Volver al Índice
A2: H07 — PROCESOS SERCOP: Silo 2 del CININ. Contratación pública por meta PDOT. Fuente: Portal SERCOP Ecuador.
A3: ← H01
A5: ID_Proceso | B5: ID_Meta | C5: Codigo_SERCOP | D5: URL_SERCOP | E5: Objeto_Contractual | F5: Monto_Adjudicado | G5: Estado_ID | H5: Fecha_Publicacion | I5: Proveedor | J5: V_SERCOP
A6: SRC-001 | B6: PDOT-001 | C6: SIE-GADMC-001-2024 | D6: https://www.sercop.gob.ec/portal/SIE-GADMC-001-2024 | E6: Construcción acueducto rural Montecristi | F6: 2050000 | G6: ADJ | H6: 15/03/2024 | I6: Consorcio AguaClara S.A. | J6: 1
A7: SRC-002 | B7: PDOT-002 | C7: SIE-GADMC-002-2024 | D7: https://www.sercop.gob.ec/portal/SIE-GADMC-002-2024 | E7: Ampliación red alcantarillado | F7: 0 | G7: DES | H7: 45295 | I7: Sin adjudicación | J7: 0
A8: SRC-003 | B8: PDOT-003 | C8: SIE-GADMC-003-2024 | D8: https://www.sercop.gob.ec/portal/SIE-GADMC-003-2024 | E8: Sistema manejo desechos sólidos | F8: 0 | G8: CAN | H8: 20/02/2024 | I8: Proceso cancelado | J8: 0
A9: SRC-004 | B9: PDOT-004 | C9: SIE-GADMC-004-2024 | D9: https://www.sercop.gob.ec/portal/SIE-GADMC-004-2024 | E9: Mejoramiento vialidad urbana cantonal | F9: 785000 | G9: FIN | H9: 45567 | I9: Constructora VialEcuador | J9: 1
A10: SRC-005 | B10: PDOT-005 | C10: SIE-GADMC-005-2024 | D10: https://www.sercop.gob.ec/portal/SIE-GADMC-005-2024 | E10: Rehabilitación mercado municipal | F10: 360000 | G10: ADJ | H10: 28/03/2024 | I10: Constructora Mercados S.A. | J10: 1
A11: SRC-006 | B11: PDOT-006 | C11: SIE-GADMC-006-2024 | D11: https://www.sercop.gob.ec/portal/SIE-GADMC-006-2024 | E11: Construcción centro salud tipo C | F11: 0 | G11: DES | H11: 15/03/2024 | I11: Sin adjudicación | J11: 0
A12: SRC-007 | B12: PDOT-007 | C12: SIE-GADMC-007-2024 | D12: https://www.sercop.gob.ec/portal/SIE-GADMC-007-2024 | E12: Equipamiento educativo rural | F12: 228000 | G12: FIN | H12: 20/02/2024 | I12: TechEdu Ecuador Cía. | J12: 1
A13: SRC-008 | B13: PDOT-008 | C13: SIE-GADMC-008-2024 | D13: https://www.sercop.gob.ec/portal/SIE-GADMC-008-2024 | E13: Construcción guardería comunitaria | F13: 0 | G13: CAN | H13: 45569 | I13: Proceso cancelado | J13: 0
A14: SRC-009 | B14: PDOT-009 | C14: SIE-GADMC-009-2024 | D14: https://www.sercop.gob.ec/portal/SIE-GADMC-009-2024 | E14: Sistema drenaje pluvial urbano | F14: 0 | G14: DES | H14: 25/03/2024 | I14: Sin adjudicación | J14: 0
A15: SRC-010 | B15: PDOT-010 | C15: SIE-GADMC-010-2024 | D15: https://www.sercop.gob.ec/portal/SIE-GADMC-010-2024 | E15: Construcción parque sector norte | F15: 108000 | G15: FIN | H15: 15/01/2024 | I15: Constructora RecreActiva | J15: 1
A16: SRC-011 | B16: PDOT-011 | C16: SIE-GADMC-011-2024 | D16: https://www.sercop.gob.ec/portal/SIE-GADMC-011-2024 | E16: Rehabilitación malecón costero | F16: 420000 | G16: EJE | H16: 45294 | I16: Grupo Turístico Manabí | J16: 1
A17: SRC-012 | B17: PDOT-012 | C17: SIE-GADMC-012-2024 | D17: https://www.sercop.gob.ec/portal/SIE-GADMC-012-2024 | E17: Adquisición unidad móvil salud | F17: 92000 | G17: ADJ | H17: 28/02/2024 | I17: MedEquip Ecuador S.A. | J17: 1
A18: SRC-013 | B18: PDOT-013 | C18: SIE-GADMC-013-2024 | D18: https://www.sercop.gob.ec/portal/SIE-GADMC-013-2024 | E18: Capacitación artesanos toquilla | F18: 43000 | G18: FIN | H18: 45566 | I18: CIDAP Ecuador | J18: 1
A19: SRC-014 | B19: PDOT-014 | C19: SIE-GADMC-014-2024 | D19: https://www.sercop.gob.ec/portal/SIE-GADMC-014-2024 | E19: Actualización catastro predial | F19: 149000 | G19: EJE | H19: 20/02/2024 | I19: GeoSistemas Ecuador | J19: 1
A20: SRC-015 | B20: PDOT-015 | C20: SIE-GADMC-015-2024 | D20: https://www.sercop.gob.ec/portal/SIE-GADMC-015-2024 | E20: Gestión LOTAIP y transparencia | F20: 68000 | G20: FIN | H20: 15/01/2024 | I20: Consultoría TransparEcu | J20: 1
A21: SRC-016 | B21: PDOT-016 | C21: SIE-GADMC-016-2024 | D21: https://www.sercop.gob.ec/portal/SIE-GADMC-016-2024 | E21: Reforestación cuencas hídricas | F21: 76000 | G21: ADJ | H21: 45295 | I21: Ambiental Verde Ecuador | J21: 1
A22: SRC-017 | B22: PDOT-017 | C22: SIE-GADMC-017-2024 | D22: https://www.sercop.gob.ec/portal/SIE-GADMC-017-2024 | E22: Bacheo y señalización vías parroquiales | F22: 205000 | G22: FIN | H22: 20/01/2024 | I22: Asfaltos y Señales S.A. | J22: 1
A23: SRC-018 | B23: PDOT-018 | C23: Sin proceso publicado | E23: Sin proceso SERCOP registrado | F23: 0 | I23: Sin proveedor | J23: 0
A24: SRC-019 | B24: PDOT-019 | C24: SIE-GADMC-019-2024 | D24: https://www.sercop.gob.ec/portal/SIE-GADMC-019-2024 | E24: Sistema recaudación electrónica municipal | F24: 84000 | G24: ADJ | H24: 15/02/2024 | I24: SoftGov Ecuador S.A. | J24: 1
A25: SRC-020 | B25: PDOT-020 | C25: SIE-GADMC-020-2024 | D25: https://www.sercop.gob.ec/portal/SIE-GADMC-020-2024 | E25: Construcción planta tratamiento aguas residuales | F25: 980000 | G25: ADJ | H25: 45297 | I25: HidroTech Ecuador | J25: 1

Sheet H08_DOCUMENTOS_LOTAIP
A1: 🔙 Volver al Índice
A2: H08 — DOCUMENTOS LOTAIP: Silo 4 del CININ. Cumplimiento Art. 7 LOTAIP por meta. Fuente: Portal LOTAIP de cada GAD.
A3: ← H01 | V_LOTAIP = 1 si más del 60% de documentos son accesibles. Alimenta V_i maleable.
A5: ID_Doc | B5: ID_Meta | C5: Literal_LOTAIP | D5: Tipo_Documento | E5: URL_LOTAIP | F5: Estado_Accesibilidad | G5: Fecha_Publicacion | H5: V_LOTAIP_Doc | I5: Obs
A6: LOT-001 | B6: PDOT-001 | C6: k | D6: Cédula Presupuestaria | E6: https://www.montecristi.gob.ec/lotaip/001-cedula.pdf | F6: Accesible | G6: 30/04/2024 | H6: 1 | I6: OK
A7: LOT-002 | B7: PDOT-001 | C7: k | D7: Contrato Adjudicación | E7: https://www.montecristi.gob.ec/lotaip/001-contrato.pdf | F7: Ausente | H7: 0 | I7: Enlace no publicado — brecha documental
A8: LOT-003 | B8: PDOT-001 | C8: k | D8: Acta Recepción Provisional | E8: https://www.montecristi.gob.ec/lotaip/001-acta.pdf | F8: Ausente | H8: 0 | I8: Sin acta disponible
A9: LOT-004 | B9: PDOT-002 | C9: k | D9: Cédula Presupuestaria | E9: https://www.montecristi.gob.ec/lotaip/002-cedula.pdf | F9: Ausente | H9: 0 | I9: Proceso desierto sin docs
A10: LOT-005 | B10: PDOT-002 | C10: k | D10: Informe SERCOP Desierto | E10: https://www.montecristi.gob.ec/lotaip/002-desierto.pdf | F10: Ausente | H10: 0 | I10: No publicado
A11: LOT-006 | B11: PDOT-002 | C11: k | D11: Justificación Técnica | E11: https://www.montecristi.gob.ec/lotaip/002-justif.pdf | F11: Ausente | H11: 0 | I11: No publicado
A12: LOT-007 | B12: PDOT-003 | C12: k | D12: Contrato EP Aseo | E12: https://www.montecristi.gob.ec/lotaip/003-contrato.pdf | F12: Ausente | H12: 0 | I12: Proceso cancelado
A13: LOT-008 | B13: PDOT-003 | C13: k | D13: Resolución Cancelación | E13: https://www.montecristi.gob.ec/lotaip/003-resolucion.pdf | F13: Ausente | H13: 0 | I13: No publicada
A14: LOT-009 | B14: PDOT-003 | C14: k | D14: Informe Técnico | E14: https://www.montecristi.gob.ec/lotaip/003-informe.pdf | F14: Ausente | H14: 0 | I14: No publicado
A15: LOT-010 | B15: PDOT-004 | C15: k | D15: Contrato Adjudicación | E15: https://www.montecristi.gob.ec/lotaip/004-contrato.pdf | F15: Accesible | G15: 28/02/2024 | H15: 1 | I15: OK
A16: LOT-011 | B16: PDOT-004 | C16: k | D16: Acta Entrega Definitiva | E16: https://www.montecristi.gob.ec/lotaip/004-acta.pdf | F16: Accesible | G16: 15/11/2024 | H16: 1 | I16: OK
A17: LOT-012 | B17: PDOT-004 | C17: k | D17: Cédula Presupuestaria | E17: https://www.montecristi.gob.ec/lotaip/004-cedula.pdf | F17: Accesible | G17: 30/04/2024 | H17: 1 | I17: OK
A18: LOT-013 | B18: PDOT-005 | C18: k | D18: Contrato Adjudicación | E18: https://www.montecristi.gob.ec/lotaip/005-contrato.pdf | F18: Roto | H18: 0 | I18: Error 404 — enlace caído
A19: LOT-014 | B19: PDOT-005 | C19: k | D19: Acta Recepción | E19: https://www.montecristi.gob.ec/lotaip/005-acta.pdf | F19: Ausente | H19: 0 | I19: Sin acta publicada
A20: LOT-015 | B20: PDOT-005 | C20: k | D20: Cédula Presupuestaria | E20: https://www.montecristi.gob.ec/lotaip/005-cedula.pdf | F20: Accesible | G20: 30/04/2024 | H20: 1 | I20: OK
A21: LOT-016 | B21: PDOT-006 | C21: k | D21: Contrato/Convenio | E21: https://www.montecristi.gob.ec/lotaip/006-contrato.pdf | F21: Ausente | H21: 0 | I21: Proceso desierto
A22: LOT-017 | B22: PDOT-006 | C22: k | D22: Informe Desierto | E22: https://www.montecristi.gob.ec/lotaip/006-desierto.pdf | F22: Ausente | H22: 0 | I22: No publicado
A23: LOT-018 | B23: PDOT-006 | C23: k | D23: Cédula Presupuestaria | E23: https://www.montecristi.gob.ec/lotaip/006-cedula.pdf | F23: Ausente | H23: 0 | I23: No publicada
A24: LOT-019 | B24: PDOT-007 | C24: k | D24: Contrato Adjudicación | E24: https://www.montecristi.gob.ec/lotaip/007-contrato.pdf | F24: Accesible | G24: 15/03/2024 | H24: 1 | I24: OK
A25: LOT-020 | B25: PDOT-007 | C25: k | D25: Acta Recepción | E25: https://www.montecristi.gob.ec/lotaip/007-acta.pdf | F25: Ausente | H25: 0 | I25: Proceso finalizado, acta no publicada
A26: LOT-021 | B26: PDOT-007 | C26: k | D26: Cédula Presupuestaria | E26: https://www.montecristi.gob.ec/lotaip/007-cedula.pdf | F26: Accesible | G26: 30/04/2024 | H26: 1 | I26: OK
A27: LOT-022 | B27: PDOT-008 | C27: k | D27: Contrato | E27: https://www.montecristi.gob.ec/lotaip/008-contrato.pdf | F27: Ausente | H27: 0 | I27: Proceso cancelado
A28: LOT-023 | B28: PDOT-008 | C28: k | D28: Resolución Cancelación | E28: https://www.montecristi.gob.ec/lotaip/008-res.pdf | F28: Ausente | H28: 0 | I28: No publicada
A29: LOT-024 | B29: PDOT-008 | C29: k | D29: Cédula Presupuestaria | E29: https://www.montecristi.gob.ec/lotaip/008-cedula.pdf | F29: Ausente | H29: 0 | I29: No publicada
A30: LOT-025 | B30: PDOT-009 | C30: k | D30: Contrato | E30: https://www.montecristi.gob.ec/lotaip/009-contrato.pdf | F30: Ausente | H30: 0 | I30: Proceso desierto
A31: LOT-026 | B31: PDOT-009 | C31: k | D31: Informe Desierto | E31: https://www.montecristi.gob.ec/lotaip/009-desierto.pdf | F31: Ausente | H31: 0 | I31: No publicado
A32: LOT-027 | B32: PDOT-009 | C32: k | D32: Cédula Presupuestaria | E32: https://www.montecristi.gob.ec/lotaip/009-cedula.pdf | F32: Ausente | H32: 0 | I32: No publicada
A33: LOT-028 | B33: PDOT-010 | C33: k | D33: Contrato Adjudicación | E33: https://www.montecristi.gob.ec/lotaip/010-contrato.pdf | F33: Accesible | G33: 28/01/2024 | H33: 1 | I33: OK
A34: LOT-029 | B34: PDOT-010 | C34: k | D34: Acta Entrega Definitiva | E34: https://www.montecristi.gob.ec/lotaip/010-acta.pdf | F34: Accesible | G34: 30/10/2024 | H34: 1 | I34: OK
A35: LOT-030 | B35: PDOT-010 | C35: k | D35: Cédula Presupuestaria | E35: https://www.montecristi.gob.ec/lotaip/010-cedula.pdf | F35: Accesible | G35: 30/04/2024 | H35: 1 | I35: OK
A36: LOT-031 | B36: PDOT-011 | C36: k | D36: Contrato En Ejecución | E36: https://www.montecristi.gob.ec/lotaip/011-contrato.pdf | F36: Accesible | G36: 20/03/2024 | H36: 1 | I36: OK
A37: LOT-032 | B37: PDOT-011 | C37: k | D37: Acta Inicio | E37: https://www.montecristi.gob.ec/lotaip/011-inicio.pdf | F37: Accesible | G37: 45295 | H37: 1 | I37: OK
A38: LOT-033 | B38: PDOT-011 | C38: k | D38: Cédula Presupuestaria | E38: https://www.montecristi.gob.ec/lotaip/011-cedula.pdf | F38: Accesible | G38: 30/04/2024 | H38: 1 | I38: OK
A39: LOT-034 | B39: PDOT-012 | C39: k | D39: Contrato Adjudicación | E39: https://www.montecristi.gob.ec/lotaip/012-contrato.pdf | F39: Accesible | G39: 15/03/2024 | H39: 1 | I39: OK — Revisar MOM-III
A40: LOT-035 | B40: PDOT-012 | C40: k | D40: Informe Brigadas Salud | E40: https://www.montecristi.gob.ec/lotaip/012-brigadas.pdf | F40: Accesible | G40: 30/06/2024 | H40: 1 | I40: Fuente del 8295% declarado
A41: LOT-036 | B41: PDOT-012 | C41: k | D41: Cédula Presupuestaria | E41: https://www.montecristi.gob.ec/lotaip/012-cedula.pdf | F41: Accesible | G41: 30/04/2024 | H41: 1 | I41: OK
...

Sheet H09_EJECUCION_PRESUPUESTARIA
A1: 🔙 Volver al Índice
A2: H09 — EJECUCIÓN PRESUPUESTARIA: Silo 3 del CININ. Devengado eSIGEF por meta. C1=abr | C2=ago | C3=dic. Fuente: e-SIGEF Ministerio Finanzas.
A3: ← H01 | T_i = Dev_Total / Codificado_Vigente. V_eSIGEF = 1 si Dev_Total > 0
A5: ID_Ejec | B5: ID_Meta | C5: Partida_Presup | D5: Codif_Inicial | E5: Reformas | F5: Codif_Vigente | G5: Dev_C1_abr | H5: Dev_C2_ago | I5: Dev_C3_dic_parcial | J5: Dev_Total_31dic | K5: T_i | L5: V_eSIGEF
A6: EJC-001 | B6: PDOT-001 | C6: 75.01.07.001 | D6: 2125000 | E6: 0 | F6: 2125000 | G6: 270938 | H6: 812813 | I6: 1806250 | J6: 1806250 | K6: =J6/F6 -> 0.85 | L6: =IF(J6>0,1,0) -> 1
A7: EJC-002 | B7: PDOT-002 | C7: 75.01.07.002 | D7: 1550000 | E7: 0 | F7: 1550000 | G7: 13950 | H7: 41850 | I7: 93000 | J7: 93000 | K7: =J7/F7 -> 0.06 | L7: =IF(J7>0,1,0) -> 1
A8: EJC-003 | B8: PDOT-003 | C8: 75.01.07.003 | D8: 450000 | E8: 0 | F8: 450000 | G8: 0 | H8: 0 | I8: 0 | J8: 0 | K8: =J8/F8 -> 0 | L8: =IF(J8>0,1,0) -> 0
A9: EJC-004 | B9: PDOT-004 | C9: 75.01.05.004 | D9: 800000 | E9: 0 | F9: 800000 | G9: 108000 | H9: 324000 | I9: 720000 | J9: 720000 | K9: =J9/F9 -> 0.9 | L9: =IF(J9>0,1,0) -> 1
A10: EJC-005 | B10: PDOT-005 | C10: 75.01.05.005 | D10: 375000 | E10: 0 | F10: 375000 | G10: 42188 | H10: 126563 | I10: 281250 | J10: 281250 | K10: =J10/F10 -> 0.75 | L10: =IF(J10>0,1,0) -> 1
A11: EJC-006 | B11: PDOT-006 | C11: 75.01.05.006 | D11: 700000 | E11: 0 | F11: 700000 | G11: 8400 | H11: 25200 | I11: 56000 | J11: 56000 | K11: =J11/F11 -> 0.08 | L11: =IF(J11>0,1,0) -> 1
A12: EJC-007 | B12: PDOT-007 | C12: 75.01.05.007 | D12: 237500 | E12: 0 | F12: 237500 | G12: 27788 | H12: 83363 | I12: 185250 | J12: 185250 | K12: =J12/F12 -> 0.78 | L12: =IF(J12>0,1,0) -> 1
A13: EJC-008 | B13: PDOT-008 | C13: 75.01.05.008 | D13: 300000 | E13: 0 | F13: 300000 | G13: 0 | H13: 0 | I13: 0 | J13: 0 | K13: =J13/F13 -> 0 | L13: =IF(J13>0,1,0) -> 0
A14: EJC-009 | B14: PDOT-009 | C14: 75.01.07.009 | D14: 525000 | E14: 0 | F14: 525000 | G14: 7875 | H14: 23625 | I14: 52500 | J14: 52500 | K14: =J14/F14 -> 0.1 | L14: =IF(J14>0,1,0) -> 1
A15: EJC-010 | B15: PDOT-010 | C15: 75.01.05.010 | D15: 112500 | E15: 0 | F15: 112500 | G15: 16875 | H15: 50625 | I15: 112500 | J15: 112500 | K15: =J15/F15 -> 1 | L15: =IF(J15>0,1,0) -> 1
A16: EJC-011 | B16: PDOT-011 | C16: 75.01.05.011 | D16: 450000 | E16: 0 | F16: 450000 | G16: 47250 | H16: 141750 | I16: 315000 | J16: 315000 | K16: =J16/F16 -> 0.7 | L16: =IF(J16>0,1,0) -> 1
A17: EJC-012 | B17: PDOT-012 | C17: 53.08.04.012 | D17: 95000 | E17: 0 | F17: 95000 | G17: 1140 | H17: 3420 | I17: 7600 | J17: 7600 | K17: =J17/F17 -> 0.08 | L17: =IF(J17>0,1,0) -> 1
... A25: EJC-020 | B25: PDOT-020 | C25: 75.01.07.020 | D25: 1050000 | E25: 0 | F25: 1050000 | G25: 31500 | H25: 94500 | I25: 210000 | J25: 210000 | K25: =J25/F25 -> 0.2 | L25: =IF(J25>0,1,0) -> 1
A27: TOTALES: | D27: =SUM(D6:D25) -> 9525000 | F27: =SUM(F6:F25) -> 9525000 | G27: =SUM(G6:G25) -> 658217 | H27: =SUM(H6:H25) -> 1974647 | J27: =SUM(J6:J25) -> 4388100 | K27: =J27/F27 -> 0.46069291

Sheet H10_INFORMES_CPCCS
A1: 🔙 Volver al Índice
A2: H10 — INFORMES CPCCS: Silo 5 del CININ. Menciones de metas en rendición de cuentas. Fuente: Informes CPCCS y discursos de alcalde.
A3: ← H01 | V_CPCCS=1 congruente; V_CPCCS=0.5 incongruente (diff>20pp); V_CPCCS=0 no mencionada
A5: ID_Mencion | B5: ID_Meta | C5: Mencionada | D5: Cumpl_Declarado_Pct | E5: Fuente | F5: Pagina | G5: Cita_Textual | H5: Congr_eSIGEF | I5: V_CPCCS
A6: CPC-001 | B6: PDOT-001 | C6: No | I6: 0
A7: CPC-002 | B7: PDOT-002 | C7: No | I7: 0
A8: CPC-003 | B8: PDOT-003 | C8: No | I8: 0
A9: CPC-004 | B9: PDOT-004 | C9: Sí | D9: 0.9 | E9: Informe | F9: 18 | G9: Se completó el mejoramiento de vías urbanas con 90% de avance al cierre del período' | H9: Congruente | I9: 1
A10: CPC-005 | B10: PDOT-005 | C10: No | I10: 0
A11: CPC-006 | B11: PDOT-006 | C11: No | I11: 0
A12: CPC-007 | B12: PDOT-007 | C12: No | I12: 0
A13: CPC-008 | B13: PDOT-008 | C13: No | I13: 0
A14: CPC-009 | B14: PDOT-009 | C14: No | I14: 0
A15: CPC-010 | B15: PDOT-010 | C15: Sí | D15: 1 | E15: Informe | F15: 22 | G15: El parque deportivo del sector norte fue inaugurado con éxito y en plena operación' | H15: Congruente | I15: 1
A16: CPC-011 | B16: PDOT-011 | C16: No | I16: 0
A17: CPC-012 | B17: PDOT-012 | C17: Sí | D17: 82.95 | E17: Ambas | F17: 31 | G17: La unidad móvil realizó 414,743 contactos de salud comunitaria, superando en 8,295% la meta de 5,000 brigadas planificadas' | H17: Incongruente | I17: 0.5
A18: CPC-013 | B18: PDOT-013 | C18: Sí | D18: 1 | E18: Informe | F18: 25 | G18: Se capacitaron 200 artesanos en técnicas de sombrero paja toquilla, completando el 100% de la meta' | H18: Congruente | I18: 1
A19: CPC-014 | B19: PDOT-014 | C19: No | I19: 0
A20: CPC-015 | B20: PDOT-015 | C20: Sí | D20: 1 | E20: Informe | F20: 28 | G20: Se publicaron los 4 informes LOTAIP trimestrales, cumpliendo al 100% el compromiso de transparencia' | H20: Congruente | I20: 1
A21: CPC-016 | B21: PDOT-016 | C21: No | I21: 0
A22: CPC-017 | B22: PDOT-017 | C22: Sí | D22: 0.9 | E22: Informe | F22: 35 | G22: Se ejecutó el bacheo de 22.5 km de vías parroquiales de los 25 km planificados' | H22: Congruente | I22: 1
A23: CPC-018 | B23: PDOT-018 | C23: No | I23: 0
A24: CPC-019 | B24: PDOT-019 | C24: Sí | D24: 0.8 | E24: Informe | F24: 40 | G24: El sistema de recaudación electrónica fue implementado en un 80%, en fase de pruebas al cierre' | H24: Congruente | I24: 1
A25: CPC-020 | B25: PDOT-020 | C25: No | I25: 0

Sheet H10B_DATOS_SIGAD
A1: 🔙 Volver al Índice
A2: H10B_DATOS_SIGAD — SILO 6: Auto-reporte ICM | SIGAD-SENPLADES | Fuente: Reportes oficiales SIGAD GAD Montecristi 2023-2024
A3: ← H01 | El ICM SIGAD es el indicador contra el que se mide la Brecha ICM-ICPI. MOM-I activa cuando ICM alto + baja representatividad presupuestaria (§3.6.1).
A5: A · IDENTIFICACIÓN DEL REPORTE SIGAD
A6: Parámetro | B6: Valor
A7: GAD_Nombre | B7: GAD Municipal de Montecristi
A8: RUC_GAD | B8: 1360001010001
A9: Tipo_GAD | B9: CANTONAL
A10: Periodo_Politico | B10: 2023-2027
A11: Responsable_Envio | B11: Sonia Xiomara Rodríguez Mero
A12: Correo_Responsable | B12: sonia.rodriguez@montecristi.gob.ec
A13: Telefono | B13: 52310052
A14: Trimestres_Enviados_2024 | B14: Programación + T1 + T2 + T3 + T4 (todos enviados)
A16: B · RESUMEN ANUAL — Universo SIGAD vs Universo SIAP
A17: Año_Fiscal | B17: Metas_Ingresadas_SIGAD | C17: Proyectos_Ingresados | D17: Monto_Total_Proyectos | E17: Monto_En_Ejecucion | F17: ICM_Oficial | G17: Metas_Universo_SIAP | H17: Presupuesto_Universo_SIAP | I17: Represent._Presup. | J17: Represent._Metas | K17: Estado_MOM_I
A18: 2023 | B18: 5 | C18: 13 | D18: 1824689.4 | E18: 1824689.4 | F18: 1 | G18: 20 | H18: 9525000 | I18: =D18/H18 -> 0.19156844 | J18: =B18/G18 -> 0.25 | K18: =IF(AND(F18>=0.8,I18<0.1),"⚠️ MOM-I ACTIVO Alta",IF(AND(F18>=0.8,I18<0.5),"⚠️ MOM-I ACTIVO Media","Sin señal")) -> ⚠️ MOM-I ACTIVO Media
A19: 2024 | B19: 9 | C19: 18 | D19: 3939101.5 | E19: 3939101.5 | F19: =H01_PARAMETROS_GENERALES!B12 -> 1 | G19: 20 | H19: 9525000 | I19: =D19/H19 -> 0.41355396 | J19: =B19/G19 -> 0.45 | K19: =IF(AND(F19>=0.8,I19<0.1),"⚠️ MOM-I ACTIVO Alta",IF(AND(F19>=0.8,I19<0.5),"⚠️ MOM-I ACTIVO 🟠 Alta","Sin señal")) -> ⚠️ MOM-I ACTIVO 🟠 Alta
A21: C · DETALLE METAS REPORTADAS EN SIGAD — Año Fiscal 2024
A22: DATO CLAVE: Solo 9 de 20 metas del universo SIAP fueron reportadas en SIGAD. ICM = 100% sobre esas 9 metas. Las 11 restantes (55%) nunca ingresaron al sistema de auto-reporte.
A23: ID_SIGAD | B23: Competencia_GAD | C23: Objetivo_PDOT | D23: Meta_Resultados_PDOT | E23: Núm_Proyectos | F23: Meta_Acum_Anual | G23: Valor_Real_Acum | H23: Pct_Avance_Meta | I23: Codificado_Final | J23: Devengado_Anual | K23: Pct_Ejec_Presup | L23: ID_Meta_SIAP | M23: En_SIGAD_2024 | N23: En_Muestra_SIAP
A24: SIGAD-001 | B24: COOPERACIÓN INTERNACIONAL | C24: Fortalecer la gestión del GAD con alianzas estratégicas | D24: Gestionar 28 convenios en 2024 para fortalecimiento institucional | E24: 2 | F24: 28 | G24: 28 | H24: 1 | I24: 1832220 | J24: 1832220 | K24: 1 | L24: PDOT-013 | M24: SI | N24: SI
A25: SIGAD-002 | B25: AGUA POTABLE — SERVICIO PÚBLICO | C25: Prever crecimiento ordenado para mejorar calidad de vida | D25: Lograr 4 adjudicaciones en 2024 para proyectos agua y alcantarillado | E25: 3 | F25: 4 | G25: 4 | H25: 1 | I25: 1434654.5 | J25: 1434654.5 | K25: 1 | L25: PDOT-001 | M25: SI | N25: SI
A26: SIGAD-003 | B26: VIALIDAD | C26: Contribuir a mantener conectividad y movilidad | D26: Intervenir 2.00 km de vías con carpeta asfáltica en 2024 | E26: 2 | F26: 2 | G26: 2 | H26: 1 | I26: 57205.91 | J26: 57205.91 | K26: 1 | L26: PDOT-004 | M26: SI | N26: SI
A27: SIGAD-004 | B27: GESTIÓN AMBIENTAL | C27: Mejorar control ambiental cantonal | D27: Implementar sistema de control de residuos sólidos en 3 parroquias | E27: 2 | F27: 3 | G27: 3 | H27: 1 | I27: 185000 | J27: 185000 | K27: 1 | L27: PDOT-016 | M27: SI | N27: SI
A28: SIGAD-005 | B28: ALCANTARILLADO | C28: Ampliar cobertura de saneamiento ambiental | D28: Construir 2,438 metros de red de alcantarillado zona Elóy Alfaro | E28: 2 | F28: 2438 | G28: 2438 | H28: 1 | I28: 198000 | J28: 198000 | K28: 1 | L28: PDOT-002 | M28: SI | N28: SI
A29: SIGAD-006 | B29: ORDENAMIENTO TERRITORIAL | C29: Modernizar sistema de planificación cantonal | D29: Actualizar 1 catastro predial urbano-rural en 2024 | E29: 1 | F29: 1 | G29: 1 | H29: 1 | I29: 95000 | J29: 95000 | K29: 1 | L29: PDOT-014 | M29: SI | N29: SI
A30: SIGAD-007 | B30: FORTALECIMIENTO INSTITUCIONAL | C30: Mejorar capacidades institucionales del GAD | D30: Capacitar 120 funcionarios en gestión municipal y sistemas | E30: 2 | F30: 120 | G30: 120 | H30: 1 | I30: 42000 | J30: 42000 | K30: 1 | L30: PDOT-019 | M30: SI | N30: SI
A31: SIGAD-008 | B31: TURISMO | C31: Fomentar turismo sostenible cantonal | D31: Organizar 49 eventos turísticos y culturales en 2024 | E31: 2 | F31: 49 | G31: 49 | H31: 1 | I31: 55021 | J31: 55021 | K31: 1 | L31: PDOT-011 | M31: SI | N31: SI
A32: SIGAD-009 | B32: DESECHOS SÓLIDOS | C32: Optimizar gestión de residuos cantonal | D32: Implementar 1 plan de gestión integral de residuos sólidos | E32: 2 | F32: 1 | G32: 1 | H32: 1 | I32: 40000 | J32: 40000 | K32: 1 | L32: PDOT-020 | M32: SI | N32: SI
A33: NO REPORTADA | B33: METAS EN MUESTRA SIAP NO REPORTADAS EN SIGAD 2024 | M33: NO
A34: (sin ID) | B34: VIALIDAD PARROQUIAL | C34: Mejorar conectividad vial rural | D34: Bacheo y señalización vías parroquiales (meta PDOT-017) | L34: PDOT-017 | M34: NO | N34: SI
A35: (sin ID) | B35: ALCANTARILLADO SANITARIO | C35: Ampliar redes de alcantarillado | D35: Planta tratamiento aguas residuales (meta PDOT-003) | L35: PDOT-003 | M35: NO | N35: SI
A36: (sin ID) | B36: INFRAESTRUCTURA SOCIAL | C36: Equipar infraestructura educativa rural | D36: Equipamiento educativo establecimientos rurales (meta PDOT-007) | L36: PDOT-007 | M36: NO | N36: SI
A37: (sin ID) | B37: SALUD | C37: Mejorar infraestructura de salud | D37: Centro de salud tipo C parroquia rural (meta PDOT-006) | L37: PDOT-006 | M37: NO | N37: SI
A38: (sin ID) | B38: MERCADO MUNICIPAL | C38: Rehabilitar infraestructura comercial | D38: Rehabilitación mercado municipal (meta PDOT-005) | L38: PDOT-005 | M38: NO | N38: SI
A39: (sin ID) | B39: DEPORTE Y RECREACIÓN | C39: Construir espacios recreativos | D39: Parque recreativo sector norte (meta PDOT-010) | L39: PDOT-010 | M39: NO | N39: SI
A40: (sin ID) | B40: INFRAESTRUCTURA SOCIAL | C40: Proveer servicios de cuidado infantil | D40: Guardería comunitaria El Carmen (meta PDOT-008) | L40: PDOT-008 | M40: NO | N40: SI
A41: (sin ID) | B41: SERVICIOS SOCIALES | C41: Atender grupos vulnerables | D41: Programa adulto mayor y discapacidad (meta PDOT-018) | L41: PDOT-018 | M41: NO | N41: SI
A43: D · ANÁLISIS MOM-I — FRAGMENTACIÓN SELECTIVA DEL UNIVERSO EVALUADO §3.6.1
A44: Todos los cálculos son fórmulas vivas — actualizan al cambiar Sección B.
...

Sheet H11_ALERTAS_MOM
A1: 🔙 Volver al Índice
A2: H11 — SEÑALES DE ATENCIÓN TEMPRANA — Protocolos MOM
A3: Estas señales indican oportunidades de mejora en la gestión programática y documental. No constituyen sanciones ni procesos disciplinarios.
A4: ← H01 | Ver H14 (ICPI) →
A5: ✅ ESPÍRITU DEL SISTEMA: Las alertas MOM son señales de atención temprana para mejorar la gestión programática y documental. No constituyen sanciones ni reemplazan la potestad de la CGE. El SIAP-ICPI habla AL GAD, no CONTRA él.
A7: MOM-I · FRAGMENTACIÓN SELECTIVA DEL UNIVERSO EVALUADO §3.6.1
A8: FRAGMENTACIÓN SELECTIVA §3.6.1: Ocurre cuando el GAD reporta cumplimiento alto en SIGAD basándose en un subconjunto pequeño del presupuesto total del PDOT, excluyendo estratégicamente las metas de mayor inversión que no fueron ejecutadas. Condición: ICM≥80% Y representatividad presupuestaria <10%. Base legal: COPFP Art. 9, 41, 54.
A9: Parámetro | B9: Valor | C9: Fórmula / Fuente | D9: Nota
A10: Presupuesto Metas Reportadas SIGAD | B10: =H10B_DATOS_SIGAD!D19 -> 3939101.5 | C10: Referencia directa a H10B_DATOS_SIGAD Sección B — Año 2024 | D10: $3,939,101 — monto real SIGAD 2024
A11: Presupuesto Total PDOT 2024 | B11: 9525000 | C11: Presupuesto anual estratégico SIAP | D11: $9,525,000 = suma presupuestos anuales 20 metas PDOT
A12: Representatividad SIGAD/PDOT | B12: =B10/B11 -> 0.41355396 | C12: =B10/B11 -> 0.41355396 | D12: ="SIGAD $"&TEXT(B10,"#,##0")&" / SIAP $"&TEXT(B11,"#,##0")&" = "&TEXT(B10/B11,"0.0%") -> SIGAD $3939101,480 / SIAP $9525000,0 = 41%
A13: ICM Reportado SIGAD | B13: =H01_PARAMETROS_GENERALES!B12 -> 1 | C13: =H01_PARAMETROS_GENERALES!B12 -> 1 | D13: ="ICM SIGAD="&TEXT(H01_PARAMETROS_GENERALES!B12,"0%")&" sobre "&TEXT(B12,"0.0%")&" del presupuesto SIAP — MOM-I "&IF(AND(B13>=0.8,B12<0.5),"ACTIVO","INACTIVO") -> ICM SIGAD=100% sobre 41% del presupuesto SIAP — MOM-I ACTIVO
A14: SEVERIDAD | B14: =IF(B12<0.2,"🔴 Alta",IF(B12<0.4,"🟠 Alta-Media",IF(B12<0.5,"💛 Media-Alta","🟡 Media"))) -> 💛 Media-Alta | C14: =IF(B12<0.2,"🔴 Alta",IF(B12<0.4,"🟠 Alta-Media",IF(B12<0.5,"💛 Media-Alta","🟡 Media"))) -> 💛 Media-Alta | D14: Umbrales: <20%=Alta | <40%=Alta-Media | <50%=Media-Alta | ≥50%=Media
A15: SEÑAL MOM-I (Automática) | B15: =IF(AND(B13>=0.8,B12<0.5),"⚠️ FRAGMENTACIÓN SELECTIVA CONFIRMADA §3.6.1: ICM="&TEXT(B13,"0%")&" sobre solo "&TEXT(B12,"0.0%")&" del presupuesto SIAP. Brecha ICM-ICPI="&TEXT(B13*100-H14_CALCULO_ICPI!B32,"0.0")&"pp. Referencia: H10B_DATOS_SIGAD.","Sin señal MOM-I") -> ⚠️ FRAGMENTACIÓN SELECTIVA CONFIRMADA §3.6.1: ICM=100% sobre solo 41% del presupuesto SIAP. Brecha ICM-ICPI=59pp. Referencia: H10B_DATOS_SIGAD. | C15: =IF(AND(B13>=0.8,B12<0.5),"⚠️ FRAGMENTACIÓN SELECTIVA CONFIRMADA §3.6.1: ICM="&TEXT(B13,"0%")&" sobre solo "&TEXT(B12,"0.0%")&" del presupuesto SIAP. Brecha ICM-ICPI="&TEXT(B13*100-H14_CALCULO_ICPI!B32,"0.0")&"pp. Referencia: H10B_DATOS_SIGAD.","Sin señal MOM-I") -> ⚠️ FRAGMENTACIÓN SELECTIVA CONFIRMADA §3.6.1: ICM=100% sobre solo 41% del presupuesto SIAP. Brecha ICM-ICPI=59pp. Referencia: H10B_DATOS_SIGAD. | D15: MOM-I §3.6.1 — Formula viva: se actualiza con H10B_DATOS_SIGAD y H01
A17: MOM-II · SUSTITUCIÓN ESTRATÉGICA DE METAS §3.6.2
A18: SUSTITUCIÓN ESTRATÉGICA §3.6.2: Ocurre cuando el GAD reforma el POA durante el año fiscal, eliminando metas complejas y costosas y sustitutyéndolas por actividades baratas y fácilmente ejecutables, sin seguir el procedimiento formal del Art. 295 COOTAD. Detectado via hash SHA-256 del POA (comparación enero vs. diciembre). Base legal: COOTAD Art. 295 + COPFP Art. 97.
A19: Parámetro | B19: Valor | C19: Descripción | D19: Nota
A20: Hash POA Aprobado (enero) | B20: a3f5c9d2e8b14f7a3c6d9e0f1b2a4c8d | C20: Huella digital POA enero 2024 | D20: Simulado - representa integridad documental
A21: Hash POA Cierre (diciembre) | B21: a3f5c9d2e8b14f7a3c6d9e0f1b2a4c8d | C21: Huella digital POA diciembre 2024 | D21: Idéntico → POA sin modificaciones
A22: Comparación de Hashes | B22: =IF(B20=B21,"✅ Hashes idénticos — POA mantiene integridad documental","⚠️ ATENCIÓN: POA modificado entre enero y diciembre") -> ✅ Hashes idénticos — POA mantiene integridad documental | C22: =IF(B20=B21,"✅ Hashes idénticos — POA mantiene integridad documental","⚠️ ATENCIÓN: POA modificado entre enero y diciembre. Revisar metas sustituidas.") -> ✅ Hashes idénticos — POA mantiene integridad documental | D22: Verificación automática
A23: SEÑAL MOM-II Global | B23: Sin señal — POA mantiene integridad documental | C23: Resultado comparación | D23: No se detectaron sustituciones sistemáticas
A24: NOTA ESPECÍFICA PDOT-006 | B24: ⚠️ Meta 'Centro Salud tipo C' declarada 'en gestión' con proceso SERCOP desierto. Revisar si existe reformulación de alcance o sustitución de meta. | C24: Análisis específico | D24: Revisar en próximo ciclo
A26: MOM-III · INFLACIÓN DE UNIDADES DE MEDIDA §3.6.3
A27: INFLACIÓN DE UNIDADES §3.6.3: Ocurre cuando el GAD mantiene formalmente el nombre de la meta original pero redefine operativamente la unidad de medida, transformando métricas verificables en métricas elásticas no verificables (ej: de 'brigadas físicas' a 'contactos'). Condición: Cumplimiento reportado >500% Y T_i <10% Y unidad_reporte ≠ unidad_PDOT. Base legal: COPFP Art. 117 + COA Art. 196.
A28: ID_Meta | B28: Meta PDOT | C28: Unidad PDOT | D28: Unidad SIGAD Reportada | E28: Cant. Planif. | F28: Cant. Reportada | G28: % Cumplimiento | H28: T_i Presup. | I28: SEÑAL MOM-III
A29: PDOT-012 | B29: Unidad móvil de salud comunitaria | C29: Unidad operativa | D29: Contactos sistema salud | E29: 1 | F29: 414743 | G29: 82.95 | H29: 0.08 | I29: ⚠️ ATENCIÓN TEMPRANA: Cumplimiento 8,295% con ejecución presupuestaria del 8%. La diferencia entre 'Unidad Móvil operativa' (PDOT) y 'contactos sistema salud' (SIGAD) sugiere redefinición operativa del indicador. Se recomienda verificación documental.
A30: Fórmula automática de detección: | C30: =IF(AND(G30>500,H30<0.1),"⚠️ SEÑAL MOM-III ACTIVA","Sin señal") -> Sin señal
A32: RESUMEN DE SEÑALES DE ATENCIÓN TEMPRANA
A33: Protocolo | B33: Estado | C33: Severidad | D33: Metas Afectadas | E33: Acción Recomendada
A34: MOM-I (Fragmentación Selectiva) | B34: ⚠️ Activa | C34: Alta | D34: PDOT-018 y múltiples no reportadas | E34: Ampliar universo de metas en SIGAD al 100% del PDOT
A35: MOM-II (Sustitución de Metas) | B35: ✅ Sin señal | C35: — | D35: — | E35: Mantener integridad documental del POA
A36: MOM-III (Inflación de Unidades) | B36: ⚠️ Activa | C36: Alta | D36: PDOT-012 | E36: Verificar definición operativa del indicador 'Unidad Móvil'
A37: SECCIÓN 4 · CLASIFICACIÓN DE SEÑALES DE ATENCIÓN TEMPRANA §3.6
A38: Clasificación técnica de señales identificadas por los protocolos MOM. Cada señal indica una oportunidad de mejora en la gestión programática.
A39: Tipo_Dictamen | B39: Código | C39: Definición | D39: Ejemplo_Aplicado | E39: Base_Legal
A40: Señal Tipo A — Brecha Documental | B40: DIC-A | C40: Desviación producida por inconsistencias en el registro, cambios no documentados en unidad de medida o errores humanos en el reporte. Sin evidencia de dolo administrativo. Afecta T_i pero no invalida la meta. | D40: Proceso SERCOP declarado desierto por especificaciones técnicas complejas | E40: COA Art. 196
