Workbook

Sheet H00_ÍNDICE
A1: 🏛️ TERRA SIAP-ICPI v2.0 | QUADRUM | B1: ⬅️ ÍNDICE GENERAL | C1: ="ICPI: "&TEXT(H12_MOTOR_ICPI_CANÓNICO!B28,"0,0")&"%" -> ICPI: 72,9% | D1: H00 — ÍNDICE
A2: 🏛️ TERRA SIAP-ICPI v2.0 — ÍNDICE GENERAL DEL ECOSISTEMA
A3: 37 hojas · 7 bloques funcionales · GAD Municipal de Montecristi | QUADRUM GovTech | NIVEL 0 — Navegación
A4: Hoja | B4: Bloque | C4: Descripción | D4: Tab_Color | E4: Estado_Sistema
A5: H00_ÍNDICE | B5: 0 — Navegación | C5: Índice navegable con ICPI en tiempo real | D5: #718096 | E5: ✅ Activa
A6: H01_PARÁMETROS | B6: 1 — Configuración | C6: Parámetros únicos del sistema TERRA | D6: #003087 | E6: ✅ Activa
A7: H02_GLOSARIO_TERRA | B7: 1 — Configuración | C7: Glosario de 15 términos técnicos TERRA | D7: #003087 | E7: ✅ Activa
A8: H03_S1_ELECTORAL_CNE | B8: 2 — Silo S1 | C8: Promesas electorales → IFE (82,5%) | D8: #3182CE | E8: ✅ Activa
A9: H04_S2_PLANIFICACIÓN_PDOT | B9: 2 — Silo S2 | C9: 20 metas PDOT — Base absoluta del sistema | D9: #3182CE | E9: ✅ Activa
A10: H05_S3_OPERATIVO_POA | B10: 2 — Silo S3 | C10: Plan Operativo Anual — ejecución mensual | D10: #3182CE | E10: ✅ Activa
A11: H06_S4_CONTRATACIÓN_SERCOP | B11: 2 — Silo S4 | C11: Contratos SERCOP — V_SERCOP verificador | D11: #3182CE | E11: ✅ Activa
A12: H07_S5_FINANCIERO_eSIGEF | B12: 2 — Silo S5 | C12: Devengado eSIGEF — T_i por meta | D12: #3182CE | E12: ✅ Activa
A13: H08_S6_AUTOREPORTE_SIGAD | B13: 2 — Silo S6 | C13: ICM auto-reportado 100% vs ICPI 72,7% | D13: #3182CE | E13: ✅ Activa
A14: H09_S7_TRANSPARENCIA_LOTAIP | B14: 2 — Silo S7 | C14: ITAM transparencia activa 90% | D14: #3182CE | E14: ✅ Activa
A15: H10_S8_PARTICIPACIÓN_CPCCS | B15: 2 — Silo S8 | C15: Rendición de cuentas CPCCS | D15: #3182CE | E15: ✅ Activa
... A41: H36_TERRA_BRIDGE | B41: 7 — Salidas | C41: Puente Web JSON — SIAP Web + TERRA Ciudadana | D41: #718096 | E41: ✅ Activa
A44: ▌ ESTADÍSTICAS DEL SISTEMA
A45: Total hojas TERRA: | B45: 37
A46: Total silos verificadores: | B46: 9
A47: Total señales SAT: | B47: 4
A48: Total índices derivados: | B48: 6
A49: ="ICPI Global en tiempo real: "&INT(H12_MOTOR_ICPI_CANÓNICO!B28)&","&TEXT(MOD(H12_MOTOR_ICPI_CANÓNICO!B28,1)*10,"0")&"% — "&H12_MOTOR_ICPI_CANÓNICO!B29 -> ICPI Global en tiempo real: 72,9% — 🟢 Gestión por Mandato

Sheet H01_PARÁMETROS
A1: 🏛️ TERRA SIAP-ICPI v2.0 | QUADRUM | B1: ⬅️ ÍNDICE GENERAL | C1: ="ICPI: "&TEXT(H12_MOTOR_ICPI_CANÓNICO!B28,"0,0")&"%" -> ICPI: 72,9% | D1: H01 — PARÁMETROS | E1: =TEXT(TODAY(),"DD/MM/YYYY") -> 05/04/2026
A2: H01 — PARÁMETROS GENERALES TERRA SIAP-ICPI v2.0
A3: FUENTE Única de toda configuración. TODAS las hojas leen de aquí. NADIE más tiene valores de configuración hardcodeados.
A5: ▌ SECCIÓN A — IDENTIFICACIÓN DEL GAD
A6: GAD_Nombre | B6: GAD Municipal de Montecristi
A7: GAD_Codigo | B7: 130801
A8: GAD_RUC | B8: 1360000430001
A9: GAD_Provincia | B9: Manabí
A10: GAD_Período | B10: 2024-2027
A11: GAD_Alcalde | B11: Ing. Jonathan Toro Largacha
A12: ICM_SIGAD_Oficial | B12: 1
A13: Fecha_Corte | B13: 2024-12-31T05:00:00.000Z
A14: Año_Fiscal | B14: 2024
A15: Total_Metas_PDOT | B15: 20
A16: Total_Promesas_CNE | B16: 25
A18: ▌ SECCIÓN B — ESCALA AVEP (5 NIVELES)
A19: Nivel | B19: Min_% | C19: Max_% | D19: Etiqueta | E19: Color_Hex | F19: Emoji
A20: 5 | B20: 90 | C20: 100 | D20: Excelencia en Gobernanza | E20: #003087 | F20: 🔵
A21: 4 | B21: 70 | C21: 89 | D21: Gestión por Mandato | E21: #38a169 | F21: 🟢
A22: 3 | B22: 40 | C22: 69 | D22: Transición Crítica | E22: #d69e2e | F22: 🟡
A23: 2 | B23: 20 | C23: 39 | D23: Gestión por Ocurrencia | E23: #e67e22 | F23: 🟠
A24: 1 | B24: 0 | C24: 19 | D24: Ruptura Sistémica | E24: #e53e3e | F24: 🔴
A25: Función AVEP estándar (referencia):
A26: =SI(valor>=90,"🔵 Excelencia en Gobernanza",SI(valor>=70,"🟢 Gestión por Mandato",SI(valor>=40,"🟡 Transición Crítica",SI(valor>=20,"🟠 Gestión por Ocurrencia","🔴 Ruptura Sistémica"))))
A27: ▌ SECCIÓN C — PARÁMETROS FISCALES Y DISCRIMINACIÓN POSITIVA
A28: Presupuesto_Total_GAD | B28: 26689147
A29: Presupuesto_Patronato (Art.249 COOTAD — 10%) | B29: =B28*0.1 -> 2668914.7
A30: Fecha_Reforma_COOTAD | B30: 2026-02-23T05:00:00.000Z
A31: Fecha_Vigencia_Regla_Fiscal | B31: 2026-06-01T05:00:00.000Z
A32: Pct_Inversion_Minimo | B32: 0.65
A33: Pct_Corriente_Maximo | B33: 0.35
A34: SAT_IV_Activa [MALEABLE: actualizar B31 si reforma COOTAD derogada] | B34: =IF(B13>=B31,"SÍ","NO") -> NO
A35: --- DISCRIMINACIÓN POSITIVA — Módulo TERRA Ciudadano ---
A36: Multiplicador_Clima [Bono 15% para metas ODS 13 — Resiliencia] | B36: 1.15
A37: Multiplicador_Genero [Bono 15% para metas ODS 5 — Igualdad] | B37: 1.15
A38: Nota discriminación positiva: | B38: Estos multiplicadores elevan el R_i de metas de género y clima en H04, haciendo que su incumplimiento penalice más el IED. La fórmula canónica del motor NO cambia.
A40: ▌ SECCIÓN D — UMBRALES SEÑALES SAT
A41: SAT_I_Umbral_ICM | B41: 0.8
A42: SAT_I_Umbral_Universo | B42: 0.1
A43: SAT_II_Umbral_Reforma | B43: 0.05
...

Sheet H02_GLOSARIO_TERRA
A1: 🏛️ TERRA SIAP-ICPI v2.0 | QUADRUM | B1: ⬅️ ÍNDICE GENERAL | C1: ="ICPI: "&TEXT(H12_MOTOR_ICPI_CANÓNICO!B28,"0,0")&"%" -> ICPI: 72,9% | D1: H02 — GLOSARIO | E1: =TEXT(TODAY(),"DD/MM/YYYY") -> 05/04/2026
A2: H02 — GLOSARIO TERRA — 15 TÉRMINOS CANÓNICOS
A3: Los únicos términos propios del ecosistema. NO se inventan otros.
A5: # | B5: Sigla | C5: Término Completo | D5: Definición | E5: Ref. Legal
A6: 1 | B6: TERRA | C6: Ecosistema de Integridad Algorítmica Preventiva | D6: Plataforma GovTech de QUADRUM para gobernanza preventiva municipal | E6: COOTAD Art.295
A7: 2 | B7: SIAP | C7: Sistema de Integridad Algorítmica Preventiva | D7: Arquitectura metodológica de verificación cruzada intersistémica para GADs | E7: COOTAD Art.295 + COPFP Art.9
A8: 3 | B8: ICPI | C8: Índice de Congruencia Programática e Intersistémica | D8: Métrica nuclear que certifica alineación verificable entre PDOT y ejecución en 9 silos | E8: COPFP Art.54
A9: 4 | B9: IFE | C9: Índice de Fidelidad Electoral | D9: Verificador complementario. Mide si las promesas del Plan CNE fueron incorporadas al PDOT. NO es motor de cálculo. | E9: Código Democracia
A10: 5 | B10: IED | C10: Índice de Eficiencia Directiva | D10: ICPI desagregado por silo y dirección. Evalúa calidad del flujo administrativo. | E10: LOSEP Art.76 + NCI 200-04
A11: 6 | B11: ITAM | C11: Índice de Transparencia Activa Municipal | D11: Calidad y accesibilidad documental en los silos públicos del GAD | E11: LOTAIP Art.7
A12: 7 | B12: ICS | C12: Índice de Congruencia Social | D12: ICPI filtrado para metas sociales y grupos de atención prioritaria | E12: Constitución Art.35
A13: 8 | B13: ISP | C13: Índice de Congruencia del Patronato | D13: Trazabilidad del gasto social delegado. Componente opcional del ICS. | E13: COOTAD Art.249
A14: 9 | B14: ICODS | C14: Índice de Congruencia ODS | D14: Alineación de metas PDOT con Agenda 2030. Incluye subíndice género y generacional. | E14: ODS 16-17 prioritarios
A15: 10 | B15: MOM | C15: Mutación del Objeto de Medición | D15: Gaming del sistema de autoreporte municipal. Tres tipos detectados algorítmicamente. | E15: Campbell 1976 + Hood 2006
A16: 11 | B16: SAT | C16: Señales de Atención Temprana | D16: Cuatro protocolos algorítmicos de detección de anomalías en la cadena de trazabilidad. | E16: COPFP Art.117 + COA Art.196
A17: 12 | B17: CIIN | C17: Cadena de Trazabilidad Intersistémica | D17: Flujo documental con firma digital desde informe mensual de servidor hasta CPCCS. | E17: Constitución Art.18
... A20: 15 | B20: MMP | C20: Motor de Monitoreo Programático | D20: Seguimiento mensual con firma digital por servidor público y director. Cadena de integridad intersistémica. | E20: COPFP Art.115-117
A22: # | B22: Componente | C22: Nombre Completo | D22: Descripción / Valores Permitidos | E22: Referencia
B23: ESTRUCTURA ID CANÓNICO: | C23: XX-T-E-NN | D23: Formato: Sistema (2L) – Tipo (1L) – Enfoque (1L) – Secuencial (2N) | E23: COPFP Art.54; COOTAD Art.295
A24: 1 | B24: AH | C24: Asentamientos Humanos | D24: Infraestructura vial, agua potable, alcantarillado, equipamientos y vivienda. Competencia exclusiva GAD Municipal Art.55 COOTAD. | E24: COOTAD Art.55 lit.d/e
A25: 2 | B25: SC | C25: Socio Cultural | D25: Servicios de salud municipal, protección derechos, cultura y patrimonio, TICs educativas. | E25: COOTAD Art.55 lit.b; COPFP Art.42
A26: 3 | B26: FA | C26: Físico Ambiental | D26: Gestión ambiental, riesgo, desechos sólidos, áreas verdes. Competencia municipal sobre saneamiento. | E26: COOTAD Art.55 lit.c; TULSMA
A27: 4 | B27: PI | C27: Político Institucional | D27: Planificación, talento humano, catastro, participación ciudadana, sostenibilidad financiera. | E27: COPFP Art.41; COOTAD Art.54
A28: 5 | B28: EP | C28: Económico Productivo | D28: Fomento productivo, turismo, artesanías, mipymes. Competencia concurrente. | E28: COOTAD Art.135; COPCI
A29: 6 | B29: C | C29: Competencia Exclusiva | D29: Obligación constitucional del GAD Municipal. Verificable directamente en sistemas estatales. | E29: COOTAD Art.55; CRE Art.264
A30: 7 | B30: I | C30: Competencia Inversión | D30: Inversión pública territorial. Prioridad presupuestaria de la administración. | E30: COPFP Art.58; COOTAD Art.196
A31: 8 | B31: L | C31: Competencia Concurrente | D31: Competencia compartida con otros niveles de gobierno o sector privado. | E31: COOTAD Art.136; CRE Art.260
A32: 9 | B32: X | C32: Competencia Exclusiva (Enfoque) | D32: La meta pertenece a competencias exclusivas del GAD. Máxima trazabilidad TERRA. | E32: COOTAD Art.55; COPFP Art.41
A33: 10 | B33: N | C33: Necesidades Básicas Insatisfechas | D33: La meta aborda directamente indicadores NBI. Prioridad social COPFP. | E33: COPFP Art.42; Agenda 2030 ODS 1/3/6
A34: 11 | B34: G | C34: Gobernanza e Institucionalidad | D34: La meta fortalece capacidades institucionales, transparencia y rendición de cuentas. | E34: COPFP Art.54; COOTAD Art.3 lit.g
A35: 12 | B35: NN | C35: Secuencial por Sistema | D35: Número ordinal de 2 dígitos dentro del mismo sistema (01, 02, …). Sin semántica adicional. | E35: Convención interna TERRA v2.0
A37: # | B37: ID Canónico | C37: Meta Descriptiva | D37: Sistema / Competencia | E37: ODS Primario
A38: 1 | B38: SC-I-N-01 | C38: Salud Municipal: pob. atendida 57,401→84,041 | D38: Socio Cultural / Inversión / NBI | E38: ODS 3, 1, 10
A39: 2 | B39: SC-L-N-02 | C39: TICs y educativo: 19,265→23,265 beneficiarios | D39: Socio Cultural / Concurrente / NBI | E39: ODS 4, 10
A40: 3 | B40: AH-I-X-01 | C40: Vialidad: 43.8km CUP + 57.22km rurales | D40: As. Humanos / Inversión / Exclusiva | E40: ODS 9, 11
A41: 4 | B41: AH-I-X-02 | C41: Señalización e IVU: 10.94→17.32 m²/hab | D41: As. Humanos / Inversión / Exclusiva | E41: ODS 11
A42: 5 | B42: AH-I-X-03 | C42: Equipamientos: canchas, parques, plazas, terminal | D42: As. Humanos / Inversión / Exclusiva | E42: ODS 11, 3, 4
A43: 6 | B43: AH-I-N-01 | C43: Vivienda interés social: 50 VIS hasta 2027 | D43: As. Humanos / Inversión / NBI | E43: ODS 1, 11
A44: 7 | B44: SC-L-G-01 | C44: Cultura y patrimonio: inventario 100%; 10,000 asist. | D44: Socio Cultural / Concurrente / Gobernanza | E44: ODS 4, 11
A45: 8 | B45: AH-I-X-04 | C45: Tránsito: señaliz. 10,000m²; 8 semáforos; 20k rev. | D45: As. Humanos / Inversión / Exclusiva | E45: ODS 11, 3
...

Sheet H03_S1_ELECTORAL_CNE
A1: 🏛️ TERRA SIAP-ICPI v2.0 | QUADRUM | B1: ⬅️ ÍNDICE GENERAL | C1: ="ICPI: "&TEXT(H12_MOTOR_ICPI_CANÓNICO!B28,"0,0")&"%" -> ICPI: 72,9% | D1: H03 — S1 CNE | E1: =TEXT(TODAY(),"DD/MM/YYYY") -> 05/04/2026
A2: S1 — SILO ELECTORAL (CNE) — ÍNDICE DE FIDELIDAD ELECTORAL (IFE)
A3: Plan de Trabajo CNE → promesas verificables · Origen absoluto del IFE | Código de la Democracia + LOPC Art.88 | NOTA: IFE es verificador complementario — base del ecosistema es H04
A5: ID_Promesa | B5: Eje_Estratégico | C5: Descripción_Promesa | D5: ID_Meta_PDOT_Vinculada | E5: Score_IFE | F5: Tipo_Vinculación | G5: Justificación_Técnica
A6: EC-001 | B6: Económico | C6: Convertir a Montecristi en destino turístico nacional/internacional; rutas gastronómicas, ecoturísticas, eventos culturales | D6: EP-L-X-01 | E6: 1 | F6: Directa | G6: PDOT-020 (EP-02) recoge íntegramente la meta turística: 2,700→4,300 visitantes/año y 10→22 eventos, presupuesto $350k codificado
A7: EC-002 | B7: Económico | C7: Fomento al sector artesanal, MIPYMES y emprendedores; programa Ka-Larte es por Ti; Cuna de Emprendedores | D7: EP-L-N-01 | E7: 1 | F7: Directa | G7: PDOT-019 (EP-01) recoge el programa artesanal y mipymes con indicador de beneficiarios y presupuesto $230k codificado
A8: EC-003 | B8: Económico | C8: Gestión para repotenciar y ordenar el mercado municipal | D8: PI-I-G-01 | E8: 0.75 | F8: Directa | G8: AH-04 (PDOT-009) incluye 'Gestión para el desarrollo del Mercado de Montecristi' como proyecto estratégico; sin presupuesto exclusivo segregado
A9: EC-004 | B9: Económico | C9: Impulsar desarrollo turístico Playa San José e Isla de la Plata; manglar; Paseo Lúdico | D9: EP-L-X-01 | E9: 0.5 | F9: Parcial | G9: Parcialmente recogida en EP-02; Manglar y Paseo Lúdico aparecen como subproyectos sin indicador cuantitativo propio
A10: EC-005 | B10: Económico | C10: Generación de ordenanzas para exoneración de tributos a nuevas empresas; alianzas sector privado para atracción de inversión | D10: — | E10: 0 | F10: Sin vínculo | G10: No existe meta en el PDOT 2023-2027 con indicador de ordenanzas tributarias ni atracción de inversión privada directa
A11: IN-001 | B11: Institucional | C11: Elaborar PDOT 2023 con ODS; planificación territorial 30 años; Plan Bicentenario | D11: PI-I-G-02 | E11: 1 | F11: Directa | G11: PDOT-017 (PI-05) recoge explícitamente cumplimiento PDOT/PUGS 0%→80% y 37 trámites en línea; el Plan Bicentenario fue elaborado y aprobado
A12: IN-002 | B12: Institucional | C12: Actualización catastral urbana y rural; base de datos grupos vulnerables; registro y delimitación comunal | D12: AH-C-X-02 | E12: 1 | F12: Directa | G12: PDOT-011 (PI-04) — catastro urbano-rural 19.52%→80%, 12 procesos sistematizados, 37 trámites en línea. Registro comunal como subactividad
A13: IN-003 | B13: Institucional | C13: Transformación digital del GAD; plataforma digital de trámites; gobierno electrónico abierto; mejora equipos informáticos | D13: AH-C-X-02 | E13: 0.75 | F13: Directa | G13: Transformación digital incluida en PI-04 como componente (37 trámites en línea); no tiene meta exclusiva de gobierno digital con indicador propio
A14: IN-004 | B14: Institucional | C14: Acceso a información pública (LOTAIP); rendición de cuentas transparente; convenios interinstitucionales nacionales e internacionales | D14: PI-L-G-01 | E14: 1 | F14: Directa | G14: PDOT-018 (PI-07) + PDOT-017 (PI-05) recogen participación ciudadana, rendición de cuentas y 4 instancias participativas efectivas (COPFP Art.115)
A15: IN-005 | B15: Institucional | C15: Seguridad ciudadana: alarmas comunitarias, habilitación UPC Aníbal San Andrés y Colorado, cuarteles bomberos en zonas estratégicas | D15: PI-I-G-01 | E15: 0.5 | F15: Parcial | G15: AH-04 incluye 'Gestión para la Construcción de la Estación Bomberil Parroquia Colorado'; alarmas comunitarias y UPC sin meta ni indicador en PDOT
A16: IN-006 | B16: Institucional | C16: Creación y fortalecimiento de marca ciudad Montecristi; posicionamiento nacional como referente de transformación | D16: — | E16: 0 | F16: Sin vínculo | G16: Sin meta verificable en PDOT: la 'marca ciudad' no tiene indicador cuantificable ni presupuesto exclusivo auditables en ningún silo TERRA
A17: SC-001 | B17: Social | C17: Construcción Centro de Salud Tipo C; construcción Centro Geriátrico; Plan Nacer Aquí; Concejo de Salud Montecristi | D17: AH-I-X-03 | E17: 1 | F17: Directa | G17: PDOT-005 (AH-04) incluye 'Gestión para obtención Centro de Salud tipo C' y SC-01 incluye 'Gestión para Centro Geriátrico Montecristi' como proyectos estratégicos
... A30: TE-005 | B30: Territorial | C30: Construcción camal municipal para faenamiento de carne fresca de calidad; control sanitario y ambiental | D30: — | E30: 0 | F30: Sin vínculo | G30: No existe meta ni proyecto en el PDOT 2023-2027 que contemple el camal municipal con indicador cuantificable ni presupuesto codificado
A31: ■ CÁLCULO IFE — FUENTE Única DEL SISTEMA | B31: ="El GAD convirtió el "&TEXT(B34,"0.0")&"% de sus promesas electorales en metas estratégicas del PDOT." -> El GAD convirtió el 77% de sus promesas electorales en metas estratégicas del PDOT.
A32: IFE_Numerador | B32: =SUM(E6:E30) -> 19.25 | C32: [Suma de scores IFE de las 25 promesas]
A33: IFE_Total_Promesas | B33: =H01_PARÁMETROS!B16 -> 25 | C33: [Lee de H01_PARÁMETROS!B16 = 25]
A34: ★ IFE_GLOBAL ★ [FUENTE Única DEL IFE] | B34: =B32/B33*100 -> 77 | C34: [★★★ CELDA MAESTRA IFE — H16 y H28 referencian única y exclusivamente esta celda ★★★]
A35: Clasificación_IFE | B35: =IF(B34>=85,"✅ Alta Fidelidad Electoral",IF(B34>=60,"⚠️ Fidelidad Moderada",IF(B34>=40,"U0001f7e0 Erosión del Compromiso","U0001f534 Ruptura del Mandato Democrático"))) -> ⚠️ Fidelidad Moderada

Sheet H04_S2_PLANIFICACIÓN_PDOT
A1: 🏛️ TERRA SIAP-ICPI v2.0 | QUADRUM | B1: ⬅️ ÍNDICE GENERAL | C1: ="ICPI: "&TEXT(H12_MOTOR_ICPI_CANÓNICO!B28,"0,0")&"%" -> ICPI: 72,9% | D1: H04 — S2 PDOT | E1: =TEXT(TODAY(),"DD/MM/YYYY") -> 05/04/2026
A2: S2 — SILO PLANIFICACIÓN ESTRATÉGICA (PDOT) — BASE ABSOLUTA DEL ECOSISTEMA TERRA
A3: PDOT quinquenal aprobado mediante ordenanza · 20 metas · Base inmutable | COOTAD Art.295 + COPFP Arts.41-42 | NOTA: Esta hoja nunca se modifica una vez cargada
A5: ID_Meta | B5: Descripción | C5: Eje_Estratégico | D5: Competencia_GAD | E5: R_i_raw | F5: Presup_PDOT_Total | G5: Presup_Anual | H5: P_i | I5: ODS_Cluster | J5: ODS_Específico | K5: Bono_Equidad | L5: R_i_final | M5: Fuente_Financiamiento | N5: Meta_Cuantitativa | O5: Unidad_Medida_ORIGINAL ⚠️INMUTABLE | P5: Línea_Base | Q5: Indicador_PDOT | R5: Dirección_Responsable | S5: Página_PDOT | T5: Vinculación_IFE
A6: SC-I-N-01 | B6: Agua potable: cobertura 39.25%→42.38%; calidad 100% INEN 1108; infraestructura BUENA 22.74%→41.64% | C6: Territorial | D6: Exclusiva_Crítica | E6: 1.5 | F6: 46904874 | G6: 11726219 | H6: =G6/SUM($G$6:$G$25) -> 0.28912002 | I6: Infraestructura | J6: 6,3,11 | K6: =IF(ISNUMBER(SEARCH("13",J6)),H01_PARÁMETROS!$B$36,IF(ISNUMBER(SEARCH("5",J6)),H01_PARÁMETROS!$B$37,1)) -> 1 | L6: {=(E6*K6)/SUMPRODUCT(MAX($E$6:$E$25*$K$6:$K$25))} -> 0.86956522 | M6: Recursos propios + BDE + MIDUVI | N6: 42.38 | O6: % cobertura agua potable | P6: 39.25 | Q6: Porcentaje de cobertura de agua potable cantonal al 42.38% hasta 2027 | R6: Patronato Municipal | S6: 363 | T6: =IF(COUNTIF(H03_S1_ELECTORAL_CNE!D:D,A6)>0,"✅ Vinculada CNE","⚠️ Sin vínculo electoral") -> ✅ Vinculada CNE
A7: SC-L-N-02 | B7: Gestión del talento humano municipal: desempeño 80%→90%; plan capacitación 90% anual | C7: Institucional | D7: Exclusiva_Importante | E7: 1 | F7: 52776878 | G7: 13194220 | H7: =G7/SUM($G$6:$G$25) -> 0.32531485 | I7: Gobernanza | J7: 16 | K7: =IF(ISNUMBER(SEARCH("13",J7)),H01_PARÁMETROS!$B$36,IF(ISNUMBER(SEARCH("5",J7)),H01_PARÁMETROS!$B$37,1)) -> 1 | L7: {=(E7*K7)/SUMPRODUCT(MAX($E$6:$E$25*$K$6:$K$25))} -> 0.57971014 | M7: Recursos propios GAD | N7: 90 | O7: % nivel desempeño personal | P7: 80 | Q7: Porcentaje de cumplimiento del nivel de desempeño institucional al 90% hasta 2027 | R7: Dirección TIC | S7: 367 | T7: =IF(COUNTIF(H03_S1_ELECTORAL_CNE!D:D,A7)>0,"✅ Vinculada CNE","⚠️ Sin vínculo electoral") -> ✅ Vinculada CNE
A8: AH-I-X-01 | B8: Sostenibilidad financiera: autonomía 43.35%→45.30%; gestión cobros y coactivas | C8: Institucional | D8: Exclusiva_Importante | E8: 1 | F8: 20205706 | G8: 5051427 | H8: =G8/SUM($G$6:$G$25) -> 0.12454728 | I8: Gobernanza | J8: 16,17 | K8: =IF(ISNUMBER(SEARCH("13",J8)),H01_PARÁMETROS!$B$36,IF(ISNUMBER(SEARCH("5",J8)),H01_PARÁMETROS!$B$37,1)) -> 1 | L8: {=(E8*K8)/SUMPRODUCT(MAX($E$6:$E$25*$K$6:$K$25))} -> 0.57971014 | M8: Recursos propios GAD | N8: 45.3 | O8: % autonomía financiera | P8: 43.35 | Q8: Porcentaje de autonomía financiera (ingresos propios / ingresos totales - financiamiento) al 45.30% hasta 2027 | R8: Dirección de Obras Públicas | S8: 367 | T8: =IF(COUNTIF(H03_S1_ELECTORAL_CNE!D:D,A8)>0,"✅ Vinculada CNE","⚠️ Sin vínculo electoral") -> ✅ Vinculada CNE
A9: AH-I-X-02 | B9: Vialidad cantonal: mantenimiento 43.8 km vías CUP + 57.22 km rurales; 23.77 km tratamiento medio | C9: Territorial | D9: Exclusiva_Crítica | E9: 1.5 | F9: 10917761 | G9: 2729440 | H9: =G9/SUM($G$6:$G$25) -> 0.067296693 | I9: Infraestructura | J9: 9,11 | K9: =IF(ISNUMBER(SEARCH("13",J9)),H01_PARÁMETROS!$B$36,IF(ISNUMBER(SEARCH("5",J9)),H01_PARÁMETROS!$B$37,1)) -> 1 | L9: {=(E9*K9)/SUMPRODUCT(MAX($E$6:$E$25*$K$6:$K$25))} -> 0.86956522 | M9: Recursos propios + BDE | N9: 130.21 | O9: Km vías mantenidas CUP acumulado | P9: 86.41 | Q9: Kilómetros de mantenimiento de vías en el CUP incrementados a 130.21 km hasta 2027 | R9: Dirección de Obras Públicas | S9: 364 | T9: =IF(COUNTIF(H03_S1_ELECTORAL_CNE!D:D,A9)>0,"✅ Vinculada CNE","⚠️ Sin vínculo electoral") -> ⚠️ Sin vínculo electoral
A10: AH-I-X-03 | B10: Salud integral municipal: población atendida 57,401→84,041 personas (+10% anual) | C10: Social | D10: Complementaria | E10: 0.5 | F10: 5882644 | G10: 1470661 | H10: =G10/SUM($G$6:$G$25) -> 0.036260413 | I10: Inclusion | J10: 3,1,10 | K10: =IF(ISNUMBER(SEARCH("13",J10)),H01_PARÁMETROS!$B$36,IF(ISNUMBER(SEARCH("5",J10)),H01_PARÁMETROS!$B$37,1)) -> 1 | L10: {=(E10*K10)/SUMPRODUCT(MAX($E$6:$E$25*$K$6:$K$25))} -> 0.28985507 | M10: Recursos propios + MSP | N10: 84041 | O10: Personas atendidas salud municipal | P10: 57401 | Q10: Número de personas atendidas en grupos de edades y por discapacidad en servicios de salud municipal | R10: Dirección de Obras Públicas | S10: 365 | T10: =IF(COUNTIF(H03_S1_ELECTORAL_CNE!D:D,A10)>0,"✅ Vinculada CNE","⚠️ Sin vínculo electoral") -> ✅ Vinculada CNE
A11: AH-I-N-01 | B11: Gestión integral desechos sólidos: 20,118→23,086 Tn/año; relleno sanitario; capacidad disposición 0%→20% | C11: Ambiental | D11: Exclusiva_Crítica | E11: 1.5 | F11: 5750745 | G11: 1437686 | H11: =G11/SUM($G$6:$G$25) -> 0.035447386 | I11: Infraestructura | J11: 11,13,3 | K11: =IF(ISNUMBER(SEARCH("13",J11)),H01_PARÁMETROS!$B$36,IF(ISNUMBER(SEARCH("5",J11)),H01_PARÁMETROS!$B$37,1)) -> 1.15 | L11: {=(E11*K11)/SUMPRODUCT(MAX($E$6:$E$25*$K$6:$K$25))} -> 1 | M11: Recursos propios GAD | N11: 23086.94 | O11: Toneladas de desechos gestionadas/año | P11: 20118.96 | Q11: Toneladas de desechos sólidos gestionadas anualmente hasta 23,086.94 Tn/año al 2027 | R11: EP Montehogar | S11: 362 | T11: =IF(COUNTIF(H03_S1_ELECTORAL_CNE!D:D,A11)>0,"✅ Vinculada CNE","⚠️ Sin vínculo electoral") -> ✅ Vinculada CNE
A12: SC-L-G-01 | B12: Alcantarillado sanitario: cobertura 19.77%→24.32%; PTAR 0%→75%; estaciones bombeo 36%→72% | C12: Territorial | D12: Exclusiva_Crítica | E12: 1.5 | F12: 1269859 | G12: 317465 | H12: =G12/SUM($G$6:$G$25) -> 0.0078273729 | I12: Infraestructura | J12: 6,3,11 | K12: =IF(ISNUMBER(SEARCH("13",J12)),H01_PARÁMETROS!$B$36,IF(ISNUMBER(SEARCH("5",J12)),H01_PARÁMETROS!$B$37,1)) -> 1 | L12: {=(E12*K12)/SUMPRODUCT(MAX($E$6:$E$25*$K$6:$K$25))} -> 0.86956522 | M12: Recursos propios + BDE | N12: 24.32 | O12: % cobertura alcantarillado sanitario | P12: 19.77 | Q12: Porcentaje de cobertura de red pública de alcantarillado sanitario al 24.32% hasta 2027 | R12: Dirección de Cultura y Deporte | S12: 363 | T12: =IF(COUNTIF(H03_S1_ELECTORAL_CNE!D:D,A12)>0,"✅ Vinculada CNE","⚠️ Sin vínculo electoral") -> ⚠️ Sin vínculo electoral
A13: AH-I-X-04 | B13: Modernización recursos administrativos: parque automotor, tecnología e infraestructura municipal | C13: Institucional | D13: Exclusiva_Importante | E13: 1 | F13: 3765021 | G13: 941255 | H13: =G13/SUM($G$6:$G$25) -> 0.023207452 | I13: Gobernanza | J13: 16 | K13: =IF(ISNUMBER(SEARCH("13",J13)),H01_PARÁMETROS!$B$36,IF(ISNUMBER(SEARCH("5",J13)),H01_PARÁMETROS!$B$37,1)) -> 1 | L13: {=(E13*K13)/SUMPRODUCT(MAX($E$6:$E$25*$K$6:$K$25))} -> 0.57971014 | M13: Recursos propios GAD | N13: 1 | O13: Parque automotor y tecnología renovados | P13: 0 | Q13: Optimización y modernización de gestión de recursos administrativos municipales ejecutada | R13: Dirección de Obras Públicas | S13: 367 | T13: =IF(COUNTIF(H03_S1_ELECTORAL_CNE!D:D,A13)>0,"✅ Vinculada CNE","⚠️ Sin vínculo electoral") -> ✅ Vinculada CNE
A14: PI-I-G-01 | B14: Equipamientos públicos: terminal terrestre, mercado, estación bomberil, centro salud tipo C, mantenimiento espacios recreativos | C14: Territorial | D14: Exclusiva_Importante | E14: 1 | F14: 2588556 | G14: 647139 | H14: =G14/SUM($G$6:$G$25) -> 0.015955769 | I14: Infraestructura | J14: 11,3,4 | K14: =IF(ISNUMBER(SEARCH("13",J14)),H01_PARÁMETROS!$B$36,IF(ISNUMBER(SEARCH("5",J14)),H01_PARÁMETROS!$B$37,1)) -> 1 | L14: {=(E14*K14)/SUMPRODUCT(MAX($E$6:$E$25*$K$6:$K$25))} -> 0.57971014 | M14: Recursos propios GAD | N14: 10.73 | O14: m² / hab índice equipamiento urbano CUP | P14: 9.96 | Q14: Índice de equipamiento urbano en el Centro Urbano Principal incrementado a 10.73 m²/hab hasta 2027 | R14: Dirección Administrativa | S14: 364 | T14: =IF(COUNTIF(H03_S1_ELECTORAL_CNE!D:D,A14)>0,"✅ Vinculada CNE","⚠️ Sin vínculo electoral") -> ✅ Vinculada CNE
A15: AH-C-X-01 | B15: Protección derechos sociales: atenciones grupos prioritarios 943→1,649 (+15%/año); CDI; adultos mayores; violencia de género | C15: Social | D15: Complementaria | E15: 0.5 | F15: 1755066 | G15: 438767 | H15: =G15/SUM($G$6:$G$25) -> 0.010818178 | I15: Inclusion | J15: 1,3,5,10 | K15: =IF(ISNUMBER(SEARCH("13",J15)),H01_PARÁMETROS!$B$36,IF(ISNUMBER(SEARCH("5",J15)),H01_PARÁMETROS!$B$37,1)) -> 1.15 | L15: {=(E15*K15)/SUMPRODUCT(MAX($E$6:$E$25*$K$6:$K$25))} -> 0.33333333 | M15: Recursos propios + Patronato | N15: 1649 | O15: Atenciones en programas grupos prioritarios | P15: 943 | Q15: Número de atenciones en programas para grupos de atención prioritaria incrementado a 1,649 hasta 2027 | R15: Dirección de Agua y Saneamiento | S15: 366 | T15: =IF(COUNTIF(H03_S1_ELECTORAL_CNE!D:D,A15)>0,"✅ Vinculada CNE","⚠️ Sin vínculo electoral") -> ✅ Vinculada CNE
A16: AH-C-X-02 | B16: Sistema información territorial: catastro urbano-rural 19.52%→80%; 12 procesos sistematizados; 37 trámites en línea | C16: Institucional | D16: Exclusiva_Importante | E16: 1 | F16: 1819567 | G16: 454892 | H16: =G16/SUM($G$6:$G$25) -> 0.011215754 | I16: Gobernanza | J16: 11,16 | K16: =IF(ISNUMBER(SEARCH("13",J16)),H01_PARÁMETROS!$B$36,IF(ISNUMBER(SEARCH("5",J16)),H01_PARÁMETROS!$B$37,1)) -> 1 | L16: {=(E16*K16)/SUMPRODUCT(MAX($E$6:$E$25*$K$6:$K$25))} -> 0.57971014 | M16: Recursos propios GAD | N16: 80 | O16: % levantamiento SIL catastro urbano-rural | P16: 19.52 | Q16: Porcentaje del sistema de información local (catastro urbano-rural) incrementado al 80% hasta 2027 | R16: Dirección de Agua y Saneamiento | S16: 367 | T16: =IF(COUNTIF(H03_S1_ELECTORAL_CNE!D:D,A16)>0,"✅ Vinculada CNE","⚠️ Sin vínculo electoral") -> ✅ Vinculada CNE
A17: SC-I-N-03 | B17: Participación ciudadana: 50→100 Unidades Territoriales participativas; 2→4 instancias efectivas (COPFP Art.115) | C17: Institucional | D17: Exclusiva_Importante | E17: 1 | F17: 137900 | G17: 34475 | H17: =G17/SUM($G$6:$G$25) -> 0.0008500108 | I17: Gobernanza | J17: 16,17 | K17: =IF(ISNUMBER(SEARCH("13",J17)),H01_PARÁMETROS!$B$36,IF(ISNUMBER(SEARCH("5",J17)),H01_PARÁMETROS!$B$37,1)) -> 1 | L17: {=(E17*K17)/SUMPRODUCT(MAX($E$6:$E$25*$K$6:$K$25))} -> 0.57971014 | M17: Recursos propios GAD | N17: 100 | O17: Unidades Territoriales participativas activas | P17: 50 | Q17: Número de Unidades Territoriales participativas incrementado a 100 hasta 2027 | R17: Patronato Municipal | S17: 368 | T17: =IF(COUNTIF(H03_S1_ELECTORAL_CNE!D:D,A17)>0,"✅ Vinculada CNE","⚠️ Sin vínculo electoral") -> ⚠️ Sin vínculo electoral
A18: FA-I-X-01 | B18: Gestión del riesgo: reducir 10% infraestructura susceptible (3,655→2,398 unidades); alerta temprana climática | C18: Ambiental | D18: Exclusiva_Importante | E18: 1 | F18: 950000 | G18: 237500 | H18: =G18/SUM($G$6:$G$25) -> 0.005855767 | I18: Infraestructura | J18: 11,13 | K18: =IF(ISNUMBER(SEARCH("13",J18)),H01_PARÁMETROS!$B$36,IF(ISNUMBER(SEARCH("5",J18)),H01_PARÁMETROS!$B$37,1)) -> 1.15 | L18: {=(E18*K18)/SUMPRODUCT(MAX($E$6:$E$25*$K$6:$K$25))} -> 0.66666667 | M18: Recursos propios GAD | N18: 2398.05 | O18: Unidades infraestructura susceptible (meta reducción) | P18: 3655 | Q18: Número de infraestructura susceptible a riesgos reducida al 10% hasta 2027 | R18: Dirección Ambiental | S18: 362 | T18: =IF(COUNTIF(H03_S1_ELECTORAL_CNE!D:D,A18)>0,"✅ Vinculada CNE","⚠️ Sin vínculo electoral") -> ⚠️ Sin vínculo electoral
A19: FA-C-X-01 | B19: Áreas verdes y parques: IVU 10.94→17.32 m²/hab; parques inter-barriales; recuperación manglar perfil costero | C19: Ambiental | D19: Exclusiva_Importante | E19: 1 | F19: 709999 | G19: 177500 | H19: =G19/SUM($G$6:$G$25) -> 0.0043764153 | I19: Infraestructura | J19: 11,13,15 | K19: =IF(ISNUMBER(SEARCH("13",J19)),H01_PARÁMETROS!$B$36,IF(ISNUMBER(SEARCH("5",J19)),H01_PARÁMETROS!$B$37,1)) -> 1.15 | L19: {=(E19*K19)/SUMPRODUCT(MAX($E$6:$E$25*$K$6:$K$25))} -> 0.66666667 | M19: Recursos propios GAD | N19: 17.32 | O19: m²/hab índice verde urbano | P19: 10.94 | Q19: Índice verde urbano consolidado y áreas recreativas incrementado a 17.32 m²/hab hasta 2027 | R19: EP Aseo Montecristi | S19: 362 | T19: =IF(COUNTIF(H03_S1_ELECTORAL_CNE!D:D,A19)>0,"✅ Vinculada CNE","⚠️ Sin vínculo electoral") -> ✅ Vinculada CNE
A20: FA-I-X-02 | B20: Índice equipamiento urbano CUP 9.96→10.73 m²/hab; recolección desechos 91.95%→97.95%; 77.83→81.07 km/día barrido | C20: Territorial | D20: Exclusiva_Importante | E20: 1 | F20: 5001963 | G20: 1250491 | H20: =G20/SUM($G$6:$G$25) -> 0.030831932 | I20: Infraestructura | J20: 11 | K20: =IF(ISNUMBER(SEARCH("13",J20)),H01_PARÁMETROS!$B$36,IF(ISNUMBER(SEARCH("5",J20)),H01_PARÁMETROS!$B$37,1)) -> 1 | L20: {=(E20*K20)/SUMPRODUCT(MAX($E$6:$E$25*$K$6:$K$25))} -> 0.57971014 | M20: Recursos propios GAD | N20: 97.95 | O20: % cobertura recolección desechos | P20: 91.95 | Q20: Porcentaje de cobertura de recolección de desechos incrementado al 97.95% hasta 2027 | R20: Dirección Ambiental | S20: 365 | T20: =IF(COUNTIF(H03_S1_ELECTORAL_CNE!D:D,A20)>0,"✅ Vinculada CNE","⚠️ Sin vínculo electoral") -> ✅ Vinculada CNE
A21: FA-L-N-01 | B21: Inventario patrimonial 100% al 2026; 8,000→10,000 participantes eventos culturales; Museo del Sombrero | C21: Social | D21: Exclusiva_Importante | E21: 1 | F21: 498449 | G21: 124612 | H21: =G21/SUM($G$6:$G$25) -> 0.0030724161 | I21: Inclusion | J21: 4,11 | K21: =IF(ISNUMBER(SEARCH("13",J21)),H01_PARÁMETROS!$B$36,IF(ISNUMBER(SEARCH("5",J21)),H01_PARÁMETROS!$B$37,1)) -> 1 | L21: {=(E21*K21)/SUMPRODUCT(MAX($E$6:$E$25*$K$6:$K$25))} -> 0.57971014 | M21: Recursos propios GAD | N21: 10000 | O21: Participantes anuales en eventos culturales | P21: 8000 | Q21: Número de participantes en eventos culturales incrementado a 10,000 hasta 2027 | R21: Dirección Ambiental | S21: 366 | T21: =IF(COUNTIF(H03_S1_ELECTORAL_CNE!D:D,A21)>0,"✅ Vinculada CNE","⚠️ Sin vínculo electoral") -> ✅ Vinculada CNE
A22: PI-I-G-02 | B22: Cumplimiento PDOT/PUGS 0%→80%; SIL 19.52%→80%; 37 trámites digitales implementados | C22: Institucional | D22: Exclusiva_Importante | E22: 1 | F22: 472973 | G22: 118243 | H22: =G22/SUM($G$6:$G$25) -> 0.002915383 | I22: Gobernanza | J22: 16,17 | K22: =IF(ISNUMBER(SEARCH("13",J22)),H01_PARÁMETROS!$B$36,IF(ISNUMBER(SEARCH("5",J22)),H01_PARÁMETROS!$B$37,1)) -> 1 | L22: {=(E22*K22)/SUMPRODUCT(MAX($E$6:$E$25*$K$6:$K$25))} -> 0.57971014 | M22: Recursos propios GAD | N22: 80 | O22: % cumplimiento PDOT/PUGS | P22: 0 | Q22: Porcentaje de proyectos del PDOT/PUGS ejecutados incrementado al 80% hasta 2027 | R22: Dirección Planificación | S22: 367 | T22: =IF(COUNTIF(H03_S1_ELECTORAL_CNE!D:D,A22)>0,"✅ Vinculada CNE","⚠️ Sin vínculo electoral") -> ✅ Vinculada CNE
A23: PI-L-G-01 | B23: Señalización vial 0→10,000 m²; 0→8 semáforos; revisiones técnicas 4,000→20,000; educación vial 40 instituciones | C23: Territorial | D23: Exclusiva_Importante | E23: 1 | F23: 270900 | G23: 67725 | H23: =G23/SUM($G$6:$G$25) -> 0.0016698182 | I23: Infraestructura | J23: 11,3 | K23: =IF(ISNUMBER(SEARCH("13",J23)),H01_PARÁMETROS!$B$36,IF(ISNUMBER(SEARCH("5",J23)),H01_PARÁMETROS!$B$37,1)) -> 1 | L23: {=(E23*K23)/SUMPRODUCT(MAX($E$6:$E$25*$K$6:$K$25))} -> 0.57971014 | M23: Recursos propios GAD | N23: 20000 | O23: Revisiones técnicas vehiculares anuales | P23: 4000 | Q23: Número de revisiones técnicas vehiculares incrementado a 20,000 hasta 2027 | R23: Dirección Planificación | S23: 364 | T23: =IF(COUNTIF(H03_S1_ELECTORAL_CNE!D:D,A23)>0,"✅ Vinculada CNE","⚠️ Sin vínculo electoral") -> ✅ Vinculada CNE
A24: EP-L-N-01 | B24: Vivienda de interés social: 50 VIS/VIP hasta 2027; reducción déficit habitacional cualitativo | C24: Territorial | D24: Exclusiva_Importante | E24: 1 | F24: 324000 | G24: 81000 | H24: =G24/SUM($G$6:$G$25) -> 0.0019971247 | I24: Infraestructura | J24: 1,11 | K24: =IF(ISNUMBER(SEARCH("13",J24)),H01_PARÁMETROS!$B$36,IF(ISNUMBER(SEARCH("5",J24)),H01_PARÁMETROS!$B$37,1)) -> 1 | L24: {=(E24*K24)/SUMPRODUCT(MAX($E$6:$E$25*$K$6:$K$25))} -> 0.57971014 | M24: Recursos propios + MIDUVI | N24: 50 | O24: Viviendas de interés social ofertadas | P24: 0 | Q24: Número de viviendas de interés social ofertadas acumuladas: 50 hasta 2027 | R24: Dirección Económica | S24: 365 | T24: =IF(COUNTIF(H03_S1_ELECTORAL_CNE!D:D,A24)>0,"✅ Vinculada CNE","⚠️ Sin vínculo electoral") -> ✅ Vinculada CNE
A25: EP-L-X-01 | B25: Fortalecimiento productivo: beneficiarios artesanos, mipymes, emprendedores, huertos comunitarios y cadenas de valor | C25: Económico | D25: Complementaria | E25: 0.5 | F25: 230363 | G25: 57591 | H25: =G25/SUM($G$6:$G$25) -> 0.0014199557 | I25: Gobernanza | J25: 1,8,10 | K25: =IF(ISNUMBER(SEARCH("13",J25)),H01_PARÁMETROS!$B$36,IF(ISNUMBER(SEARCH("5",J25)),H01_PARÁMETROS!$B$37,1)) -> 1 | L25: {=(E25*K25)/SUMPRODUCT(MAX($E$6:$E$25*$K$6:$K$25))} -> 0.28985507 | M25: Recursos propios GAD | N25: 500 | O25: Beneficiarios programas fortalecimiento productivo | P25: 0 | Q25: Número de beneficiarios de programas de formación y fortalecimiento productivo anuales | R25: Dirección Turismo | S25: 440 | T25: =IF(COUNTIF(H03_S1_ELECTORAL_CNE!D:D,A25)>0,"✅ Vinculada CNE","⚠️ Sin vínculo electoral") -> ✅ Vinculada CNE

Sheet H05_S3_OPERATIVO_POA
A1: 🏛️ TERRA SIAP-ICPI v2.0 | QUADRUM | B1: ⬅️ ÍNDICE GENERAL | C1: ="ICPI: "&TEXT(H12_MOTOR_ICPI_CANÓNICO!B28,"0,0")&"%" -> ICPI: 72,9% | D1: H05 — S3 POA | E1: =TEXT(TODAY(),"DD/MM/YYYY") -> 05/04/2026
A2: S3 — SILO OPERATIVO (POA)
A3: Plan Operativo Anual con metas desagregadas, cronograma de ejecución y responsables. Operacionaliza el PDOT en acciones ejecutables dentro del año fiscal.
A4: Fundamentación: COPFP Art.9 + COOTAD Art.234
A6: ID_Meta | B6: Descripción_Meta | C6: Dirección_Responsable | D6: Meta_Cuantitativa | E6: Unidad_Medida | F6: Presup_Anual_2024 | G6: ENE_Plan_% | H6: ENE_Ejec_% | I6: FEB_Plan_% | J6: FEB_Ejec_% | K6: MAR_Plan_% | L6: MAR_Ejec_% | M6: ABR_Plan_% | N6: ABR_Ejec_% | O6: MAY_Plan_% | P6: MAY_Ejec_% | Q6: JUN_Plan_% | R6: JUN_Ejec_% | S6: JUL_Plan_% | T6: JUL_Ejec_% | U6: AGO_Plan_% | V6: AGO_Ejec_% | W6: SEP_Plan_% | X6: SEP_Ejec_% | Y6: OCT_Plan_% | Z6: OCT_Ejec_% | AA6: NOV_Plan_% | AB6: NOV_Ejec_% | AC6: DIC_Plan_% | AD6: DIC_Ejec_% | AE6: Avance_Acum_Real | AF6: Semáforo_POA | AG6: Alerta_Inversión
A7: =H04_S2_PLANIFICACIÓN_PDOT!A6 -> SC-I-N-01 | B7: =H04_S2_PLANIFICACIÓN_PDOT!B6 -> Agua potable: cobertura 39.25%→42.38%; calidad 100% INEN 1108; infraestructura BUENA 22.74%→41.64% | C7: =H04_S2_PLANIFICACIÓN_PDOT!R6 -> Patronato Municipal | D7: =H04_S2_PLANIFICACIÓN_PDOT!N6 -> 42.38 | E7: =H04_S2_PLANIFICACIÓN_PDOT!O6 -> % cobertura agua potable | F7: =H04_S2_PLANIFICACIÓN_PDOT!G6 -> 11726219 | G7: 5 | H7: 0 | I7: 10 | J7: 0 | K7: 15 | L7: 0 | M7: 25 | N7: 0 | O7: 35 | P7: 0 | Q7: 45 | R7: 0 | S7: 55 | T7: 0 | U7: 65 | V7: 0 | W7: 75 | X7: 0 | Y7: 85 | Z7: 0 | AA7: 92 | AB7: 0 | AC7: 100 | AD7: 0 | AE7: =AVERAGE(H7,J7,L7,N7,P7,R7,T7,V7,X7,Z7,AB7,AD7) -> 0 | AF7: =IF(AC7=0,"⏸️",IF(AE7/AC7>=0.9,"🟢",IF(AE7/AC7>=0.7,"🟡","🔴"))) -> 🔴 | AG7: =IF(F7>0,"✅ Con presupuesto inversión","⚠️ SIN PRESUPUESTO — verificar clasificación") -> ✅ Con presupuesto inversión
A8: =H04_S2_PLANIFICACIÓN_PDOT!A7 -> SC-L-N-02 | B8: =H04_S2_PLANIFICACIÓN_PDOT!B7 -> Gestión del talento humano municipal: desempeño 80%→90%; plan capacitación 90% anual | C8: =H04_S2_PLANIFICACIÓN_PDOT!R7 -> Dirección TIC | D8: =H04_S2_PLANIFICACIÓN_PDOT!N7 -> 90 | E8: =H04_S2_PLANIFICACIÓN_PDOT!O7 -> % nivel desempeño personal | F8: =H04_S2_PLANIFICACIÓN_PDOT!G7 -> 13194220 | G8: 0 | H8: 0 | I8: 0 | J8: 0 | K8: 0 | L8: 0 | M8: 17 | N8: 0 | O8: 33 | P8: 0 | Q8: 50 | R8: 0 | S8: 67 | T8: 0 | U8: 83 | V8: 0 | W8: 100 | X8: 0 | Y8: 100 | Z8: 0 | AA8: 100 | AB8: 0 | AC8: 100 | AD8: 0 | AE8: =AVERAGE(H8,J8,L8,N8,P8,R8,T8,V8,X8,Z8,AB8,AD8) -> 0 | AF8: =IF(AC8=0,"⏸️",IF(AE8/AC8>=0.9,"🟢",IF(AE8/AC8>=0.7,"🟡","🔴"))) -> 🔴 | AG8: =IF(F8>0,"✅ Con presupuesto inversión","⚠️ SIN PRESUPUESTO — verificar clasificación") -> ✅ Con presupuesto inversión
A9: =H04_S2_PLANIFICACIÓN_PDOT!A8 -> AH-I-X-01 | B9: =H04_S2_PLANIFICACIÓN_PDOT!B8 -> Sostenibilidad financiera: autonomía 43.35%→45.30%; gestión cobros y coactivas | C9: =H04_S2_PLANIFICACIÓN_PDOT!R8 -> Dirección de Obras Públicas | D9: =H04_S2_PLANIFICACIÓN_PDOT!N8 -> 45.3 | E9: =H04_S2_PLANIFICACIÓN_PDOT!O8 -> % autonomía financiera | F9: =H04_S2_PLANIFICACIÓN_PDOT!G8 -> 5051427 | G9: 0 | H9: 0 | I9: 0 | J9: 0 | K9: 0 | L9: 0 | M9: 11 | N9: 0 | O9: 22 | P9: 0 | Q9: 33 | R9: 0 | S9: 44 | T9: 0 | U9: 56 | V9: 0 | W9: 67 | X9: 0 | Y9: 78 | Z9: 0 | AA9: 89 | AB9: 0 | AC9: 100 | AD9: 0 | AE9: =AVERAGE(H9,J9,L9,N9,P9,R9,T9,V9,X9,Z9,AB9,AD9) -> 0 | AF9: =IF(AC9=0,"⏸️",IF(AE9/AC9>=0.9,"🟢",IF(AE9/AC9>=0.7,"🟡","🔴"))) -> 🔴 | AG9: =IF(F9>0,"✅ Con presupuesto inversión","⚠️ SIN PRESUPUESTO — verificar clasificación") -> ✅ Con presupuesto inversión
A10: =H04_S2_PLANIFICACIÓN_PDOT!A9 -> AH-I-X-02 | B10: =H04_S2_PLANIFICACIÓN_PDOT!B9 -> Vialidad cantonal: mantenimiento 43.8 km vías CUP + 57.22 km rurales; 23.77 km tratamiento medio | C10: =H04_S2_PLANIFICACIÓN_PDOT!R9 -> Dirección de Obras Públicas | D10: =H04_S2_PLANIFICACIÓN_PDOT!N9 -> 130.21 | E10: =H04_S2_PLANIFICACIÓN_PDOT!O9 -> Km vías mantenidas CUP acumulado | F10: =H04_S2_PLANIFICACIÓN_PDOT!G9 -> 2729440 | G10: 0 | H10: 0 | I10: 0 | J10: 0 | K10: 0 | L10: 0 | M10: 0 | N10: 0 | O10: 0 | P10: 0 | Q10: 0 | R10: 0 | S10: 0 | T10: 0 | U10: 0 | V10: 0 | W10: 0 | X10: 0 | Y10: 0 | Z10: 0 | AA10: 0 | AB10: 0 | AC10: 0 | AD10: 0 | AE10: =AVERAGE(H10,J10,L10,N10,P10,R10,T10,V10,X10,Z10,AB10,AD10) -> 0 | AF10: =IF(AC10=0,"⏸️",IF(AE10/AC10>=0.9,"🟢",IF(AE10/AC10>=0.7,"🟡","🔴"))) -> ⏸️ | AG10: =IF(F10>0,"✅ Con presupuesto inversión","⚠️ SIN PRESUPUESTO — verificar clasificación") -> ✅ Con presupuesto inversión
A11: =H04_S2_PLANIFICACIÓN_PDOT!A10 -> AH-I-X-03 | B11: =H04_S2_PLANIFICACIÓN_PDOT!B10 -> Salud integral municipal: población atendida 57,401→84,041 personas (+10% anual) | C11: =H04_S2_PLANIFICACIÓN_PDOT!R10 -> Dirección de Obras Públicas | D11: =H04_S2_PLANIFICACIÓN_PDOT!N10 -> 84041 | E11: =H04_S2_PLANIFICACIÓN_PDOT!O10 -> Personas atendidas salud municipal | F11: =H04_S2_PLANIFICACIÓN_PDOT!G10 -> 1470661 | G11: 0 | H11: 0 | I11: 0 | J11: 0 | K11: 0 | L11: 0 | M11: 17 | N11: 0 | O11: 33 | P11: 0 | Q11: 50 | R11: 0 | S11: 67 | T11: 0 | U11: 83 | V11: 0 | W11: 100 | X11: 0 | Y11: 100 | Z11: 0 | AA11: 100 | AB11: 0 | AC11: 100 | AD11: 0 | AE11: =AVERAGE(H11,J11,L11,N11,P11,R11,T11,V11,X11,Z11,AB11,AD11) -> 0 | AF11: =IF(AC11=0,"⏸️",IF(AE11/AC11>=0.9,"🟢",IF(AE11/AC11>=0.7,"🟡","🔴"))) -> 🔴 | AG11: =IF(F11>0,"✅ Con presupuesto inversión","⚠️ SIN PRESUPUESTO — verificar clasificación") -> ✅ Con presupuesto inversión
A12: =H04_S2_PLANIFICACIÓN_PDOT!A11 -> AH-I-N-01 | B12: =H04_S2_PLANIFICACIÓN_PDOT!B11 -> Gestión integral desechos sólidos: 20,118→23,086 Tn/año; relleno sanitario; capacidad disposición 0%→20% | C12: =H04_S2_PLANIFICACIÓN_PDOT!R11 -> EP Montehogar | D12: =H04_S2_PLANIFICACIÓN_PDOT!N11 -> 23086.94 | E12: =H04_S2_PLANIFICACIÓN_PDOT!O11 -> Toneladas de desechos gestionadas/año | F12: =H04_S2_PLANIFICACIÓN_PDOT!G11 -> 1437686 | G12: 17 | H12: 0 | I12: 33 | J12: 0 | K12: 50 | L12: 0 | M12: 67 | N12: 0 | O12: 83 | P12: 0 | Q12: 100 | R12: 0 | S12: 100 | T12: 0 | U12: 100 | V12: 0 | W12: 100 | X12: 0 | Y12: 100 | Z12: 0 | AA12: 100 | AB12: 0 | AC12: 100 | AD12: 0 | AE12: =AVERAGE(H12,J12,L12,N12,P12,R12,T12,V12,X12,Z12,AB12,AD12) -> 0 | AF12: =IF(AC12=0,"⏸️",IF(AE12/AC12>=0.9,"🟢",IF(AE12/AC12>=0.7,"🟡","🔴"))) -> 🔴 | AG12: =IF(F12>0,"✅ Con presupuesto inversión","⚠️ SIN PRESUPUESTO — verificar clasificación") -> ✅ Con presupuesto inversión
A13: =H04_S2_PLANIFICACIÓN_PDOT!A12 -> SC-L-G-01 | B13: =H04_S2_PLANIFICACIÓN_PDOT!B12 -> Alcantarillado sanitario: cobertura 19.77%→24.32%; PTAR 0%→75%; estaciones bombeo 36%→72% | C13: =H04_S2_PLANIFICACIÓN_PDOT!R12 -> Dirección de Cultura y Deporte | D13: =H04_S2_PLANIFICACIÓN_PDOT!N12 -> 24.32 | E13: =H04_S2_PLANIFICACIÓN_PDOT!O12 -> % cobertura alcantarillado sanitario | F13: =H04_S2_PLANIFICACIÓN_PDOT!G12 -> 317465 | G13: 5 | H13: 0 | I13: 10 | J13: 0 | K13: 15 | L13: 0 | M13: 25 | N13: 0 | O13: 35 | P13: 0 | Q13: 45 | R13: 0 | S13: 55 | T13: 0 | U13: 65 | V13: 0 | W13: 75 | X13: 0 | Y13: 85 | Z13: 0 | AA13: 92 | AB13: 0 | AC13: 100 | AD13: 0 | AE13: =AVERAGE(H13,J13,L13,N13,P13,R13,T13,V13,X13,Z13,AB13,AD13) -> 0 | AF13: =IF(AC13=0,"⏸️",IF(AE13/AC13>=0.9,"🟢",IF(AE13/AC13>=0.7,"🟡","🔴"))) -> 🔴 | AG13: =IF(F13>0,"✅ Con presupuesto inversión","⚠️ SIN PRESUPUESTO — verificar clasificación") -> ✅ Con presupuesto inversión
A14: =H04_S2_PLANIFICACIÓN_PDOT!A13 -> AH-I-X-04 | B14: =H04_S2_PLANIFICACIÓN_PDOT!B13 -> Modernización recursos administrativos: parque automotor, tecnología e infraestructura municipal | C14: =H04_S2_PLANIFICACIÓN_PDOT!R13 -> Dirección de Obras Públicas | D14: =H04_S2_PLANIFICACIÓN_PDOT!N13 -> 1 | E14: =H04_S2_PLANIFICACIÓN_PDOT!O13 -> Parque automotor y tecnología renovados | F14: =H04_S2_PLANIFICACIÓN_PDOT!G13 -> 941255 | G14: 5 | H14: 0 | I14: 15 | J14: 0 | K14: 25 | L14: 0 | M14: 37 | N14: 0 | O14: 48 | P14: 0 | Q14: 60 | R14: 0 | S14: 72 | T14: 0 | U14: 84 | V14: 0 | W14: 100 | X14: 0 | Y14: 100 | Z14: 0 | AA14: 100 | AB14: 0 | AC14: 100 | AD14: 0 | AE14: =AVERAGE(H14,J14,L14,N14,P14,R14,T14,V14,X14,Z14,AB14,AD14) -> 0 | AF14: =IF(AC14=0,"⏸️",IF(AE14/AC14>=0.9,"🟢",IF(AE14/AC14>=0.7,"🟡","🔴"))) -> 🔴 | AG14: =IF(F14>0,"✅ Con presupuesto inversión","⚠️ SIN PRESUPUESTO — verificar clasificación") -> ✅ Con presupuesto inversión
A15: =H04_S2_PLANIFICACIÓN_PDOT!A14 -> PI-I-G-01 | B15: =H04_S2_PLANIFICACIÓN_PDOT!B14 -> Equipamientos públicos: terminal terrestre, mercado, estación bomberil, centro salud tipo C, mantenimiento espacios recreativos | C15: =H04_S2_PLANIFICACIÓN_PDOT!R14 -> Dirección Administrativa | D15: =H04_S2_PLANIFICACIÓN_PDOT!N14 -> 10.73 | E15: =H04_S2_PLANIFICACIÓN_PDOT!O14 -> m² / hab índice equipamiento urbano CUP | F15: =H04_S2_PLANIFICACIÓN_PDOT!G14 -> 647139 | G15: 5 | H15: 0 | I15: 10 | J15: 0 | K15: 15 | L15: 0 | M15: 25 | N15: 0 | O15: 35 | P15: 0 | Q15: 45 | R15: 0 | S15: 55 | T15: 0 | U15: 65 | V15: 0 | W15: 75 | X15: 0 | Y15: 85 | Z15: 0 | AA15: 92 | AB15: 0 | AC15: 100 | AD15: 0 | AE15: =AVERAGE(H15,J15,L15,N15,P15,R15,T15,V15,X15,Z15,AB15,AD15) -> 0 | AF15: =IF(AC15=0,"⏸️",IF(AE15/AC15>=0.9,"🟢",IF(AE15/AC15>=0.7,"🟡","🔴"))) -> 🔴 | AG15: =IF(F15>0,"✅ Con presupuesto inversión","⚠️ SIN PRESUPUESTO — verificar clasificación") -> ✅ Con presupuesto inversión
A16: =H04_S2_PLANIFICACIÓN_PDOT!A15 -> AH-C-X-01 | B16: =H04_S2_PLANIFICACIÓN_PDOT!B15 -> Protección derechos sociales: atenciones grupos prioritarios 943→1,649 (+15%/año); CDI; adultos mayores; violencia de género | C16: =H04_S2_PLANIFICACIÓN_PDOT!R15 -> Dirección de Agua y Saneamiento | D16: =H04_S2_PLANIFICACIÓN_PDOT!N15 -> 1649 | E16: =H04_S2_PLANIFICACIÓN_PDOT!O15 -> Atenciones en programas grupos prioritarios | F16: =H04_S2_PLANIFICACIÓN_PDOT!G15 -> 438767 | G16: 5 | H16: 0 | I16: 10 | J16: 0 | K16: 15 | L16: 0 | M16: 25 | N16: 0 | O16: 35 | P16: 0 | Q16: 45 | R16: 0 | S16: 55 | T16: 0 | U16: 65 | V16: 0 | W16: 75 | X16: 0 | Y16: 85 | Z16: 0 | AA16: 92 | AB16: 0 | AC16: 100 | AD16: 0 | AE16: =AVERAGE(H16,J16,L16,N16,P16,R16,T16,V16,X16,Z16,AB16,AD16) -> 0 | AF16: =IF(AC16=0,"⏸️",IF(AE16/AC16>=0.9,"🟢",IF(AE16/AC16>=0.7,"🟡","🔴"))) -> 🔴 | AG16: =IF(F16>0,"✅ Con presupuesto inversión","⚠️ SIN PRESUPUESTO — verificar clasificación") -> ✅ Con presupuesto inversión
A17: =H04_S2_PLANIFICACIÓN_PDOT!A16 -> AH-C-X-02 | B17: =H04_S2_PLANIFICACIÓN_PDOT!B16 -> Sistema información territorial: catastro urbano-rural 19.52%→80%; 12 procesos sistematizados; 37 trámites en línea | C17: =H04_S2_PLANIFICACIÓN_PDOT!R16 -> Dirección de Agua y Saneamiento | D17: =H04_S2_PLANIFICACIÓN_PDOT!N16 -> 80 | E17: =H04_S2_PLANIFICACIÓN_PDOT!O16 -> % levantamiento SIL catastro urbano-rural | F17: =H04_S2_PLANIFICACIÓN_PDOT!G16 -> 454892 | G17: 5 | H17: 0 | I17: 15 | J17: 0 | K17: 25 | L17: 0 | M17: 37 | N17: 0 | O17: 48 | P17: 0 | Q17: 60 | R17: 0 | S17: 72 | T17: 0 | U17: 84 | V17: 0 | W17: 100 | X17: 0 | Y17: 100 | Z17: 0 | AA17: 100 | AB17: 0 | AC17: 100 | AD17: 0 | AE17: =AVERAGE(H17,J17,L17,N17,P17,R17,T17,V17,X17,Z17,AB17,AD17) -> 0 | AF17: =IF(AC17=0,"⏸️",IF(AE17/AC17>=0.9,"🟢",IF(AE17/AC17>=0.7,"🟡","🔴"))) -> 🔴 | AG17: =IF(F17>0,"✅ Con presupuesto inversión","⚠️ SIN PRESUPUESTO — verificar clasificación") -> ✅ Con presupuesto inversión
A18: =H04_S2_PLANIFICACIÓN_PDOT!A17 -> SC-I-N-03 | B18: =H04_S2_PLANIFICACIÓN_PDOT!B17 -> Participación ciudadana: 50→100 Unidades Territoriales participativas; 2→4 instancias efectivas (COPFP Art.115) | C18: =H04_S2_PLANIFICACIÓN_PDOT!R17 -> Patronato Municipal | D18: =H04_S2_PLANIFICACIÓN_PDOT!N17 -> 100 | E18: =H04_S2_PLANIFICACIÓN_PDOT!O17 -> Unidades Territoriales participativas activas | F18: =H04_S2_PLANIFICACIÓN_PDOT!G17 -> 34475 | G18: 5 | H18: 0 | I18: 10 | J18: 0 | K18: 15 | L18: 0 | M18: 25 | N18: 0 | O18: 35 | P18: 0 | Q18: 45 | R18: 0 | S18: 55 | T18: 0 | U18: 65 | V18: 0 | W18: 75 | X18: 0 | Y18: 85 | Z18: 0 | AA18: 92 | AB18: 0 | AC18: 100 | AD18: 0 | AE18: =AVERAGE(H18,J18,L18,N18,P18,R18,T18,V18,X18,Z18,AB18,AD18) -> 0 | AF18: =IF(AC18=0,"⏸️",IF(AE18/AC18>=0.9,"🟢",IF(AE18/AC18>=0.7,"🟡","🔴"))) -> 🔴 | AG18: =IF(F18>0,"✅ Con presupuesto inversión","⚠️ SIN PRESUPUESTO — verificar clasificación") -> ✅ Con presupuesto inversión
... A26: =H04_S2_PLANIFICACIÓN_PDOT!A25 -> EP-L-X-01 | B26: =H04_S2_PLANIFICACIÓN_PDOT!B25 -> Fortalecimiento productivo: beneficiarios artesanos, mipymes, emprendedores, huertos comunitarios y cadenas de valor | C26: =H04_S2_PLANIFICACIÓN_PDOT!R25 -> Dirección Turismo | D26: =H04_S2_PLANIFICACIÓN_PDOT!N25 -> 500 | E26: =H04_S2_PLANIFICACIÓN_PDOT!O25 -> Beneficiarios programas fortalecimiento productivo | F26: =H04_S2_PLANIFICACIÓN_PDOT!G25 -> 57591 | G26: 5 | H26: 0 | I26: 10 | J26: 0 | K26: 15 | L26: 0 | M26: 25 | N26: 0 | O26: 35 | P26: 0 | Q26: 45 | R26: 0 | S26: 55 | T26: 0 | U26: 65 | V26: 0 | W26: 75 | X26: 0 | Y26: 85 | Z26: 0 | AA26: 92 | AB26: 0 | AC26: 100 | AD26: 0 | AE26: =AVERAGE(H26,J26,L26,N26,P26,R26,T26,V26,X26,Z26,AB26,AD26) -> 0 | AF26: =IF(AC26=0,"⏸️",IF(AE26/AC26>=0.9,"🟢",IF(AE26/AC26>=0.7,"🟡","🔴"))) -> 🔴 | AG26: =IF(F26>0,"✅ Con presupuesto inversión","⚠️ SIN PRESUPUESTO — verificar clasificación") -> ✅ Con presupuesto inversión

Sheet H06_S4_CONTRATACIÓN_SERCOP
A1: 🏛️ TERRA SIAP-ICPI v2.0 | QUADRUM | B1: ⬅️ ÍNDICE GENERAL | C1: ="ICPI: "&TEXT(H12_MOTOR_ICPI_CANÓNICO!B28,"0,0")&"%" -> ICPI: 72,9% | D1: H06 — S4 SERCOP | E1: =TEXT(TODAY(),"DD/MM/YYYY") -> 05/04/2026
A2: S4 — SILO CONTRATACIÓN PÚBLICA (SERCOP)
A3: Procesos contractuales publicados en el portal del SERCOP. Materializa las metas POA en compromisos contractuales verificables.
A4: Fundamentación: LOSNCP Art.22 + Art.73
A6: ID_Meta | B6: Descripción_Meta | C6: ID_Proceso_SERCOP | D6: Monto_Adjudicado | E6: Proveedor_RUC | F6: Estado_Proceso | G6: URL_SERCOP | H6: V_SERCOP | I6: Alerta_Sobreprecio
A7: =H04_S2_PLANIFICACIÓN_PDOT!A6 -> SC-I-N-01 | B7: =H04_S2_PLANIFICACIÓN_PDOT!B6 -> Agua potable: cobertura 39.25%→42.38%; calidad 100% INEN 1108; infraestructura BUENA 22.74%→41.64% | C7: PAC-2024-068/087/088/134 | D7: 45000 | E7: [Por adjudicar — PAC publicado] | F7: Adjudicado | G7: https://www.compraspublicas.gob.ec/ProcesoContratacion/compras/PC/buscarProceso.cpe?sg=PAC2024GADMC | H7: =IF(AND(C7<>"",F7="Adjudicado"),1,IF(C7<>"",0.5,0)) -> 1 | I7: =IF(AND(D7>0,D7>H04_S2_PLANIFICACIÓN_PDOT!G6),"⚠️ Monto supera planificación PDOT","✅ OK") -> ✅ OK
A8: =H04_S2_PLANIFICACIÓN_PDOT!A7 -> SC-L-N-02 | B8: =H04_S2_PLANIFICACIÓN_PDOT!B7 -> Gestión del talento humano municipal: desempeño 80%→90%; plan capacitación 90% anual | C8: PAC-2024-052/085 | D8: 8900 | E8: [Por adjudicar — PAC publicado] | F8: Adjudicado | G8: https://www.compraspublicas.gob.ec/ProcesoContratacion/compras/PC/buscarProceso.cpe?sg=PAC2024GADMC | H8: =IF(AND(C8<>"",F8="Adjudicado"),1,IF(C8<>"",0.5,0)) -> 1 | I8: =IF(AND(D8>0,D8>H04_S2_PLANIFICACIÓN_PDOT!G7),"⚠️ Monto supera planificación PDOT","✅ OK") -> ✅ OK
A9: =H04_S2_PLANIFICACIÓN_PDOT!A8 -> AH-I-X-01 | B9: =H04_S2_PLANIFICACIÓN_PDOT!B8 -> Sostenibilidad financiera: autonomía 43.35%→45.30%; gestión cobros y coactivas | C9: PAC-2024-027/028/033/034/039/048/062/095/098/100/164 | D9: 2206556 | E9: [Múltiples proveedores — procesos en ejecución] | F9: Adjudicado | G9: https://www.compraspublicas.gob.ec/ProcesoContratacion/compras/PC/buscarProceso.cpe?sg=PAC2024GADMC | H9: =IF(AND(C9<>"",F9="Adjudicado"),1,IF(C9<>"",0.5,0)) -> 1 | I9: =IF(AND(D9>0,D9>H04_S2_PLANIFICACIÓN_PDOT!G8),"⚠️ Monto supera planificación PDOT","✅ OK") -> ✅ OK
A10: =H04_S2_PLANIFICACIÓN_PDOT!A9 -> AH-I-X-02 | B10: =H04_S2_PLANIFICACIÓN_PDOT!B9 -> Vialidad cantonal: mantenimiento 43.8 km vías CUP + 57.22 km rurales; 23.77 km tratamiento medio | D10: 0 | H10: =IF(AND(C10<>"",F10="Adjudicado"),1,IF(C10<>"",0.5,0)) -> 0 | I10: =IF(AND(D10>0,D10>H04_S2_PLANIFICACIÓN_PDOT!G9),"⚠️ Monto supera planificación PDOT","✅ OK") -> ✅ OK
A11: =H04_S2_PLANIFICACIÓN_PDOT!A10 -> AH-I-X-03 | B11: =H04_S2_PLANIFICACIÓN_PDOT!B10 -> Salud integral municipal: población atendida 57,401→84,041 personas (+10% anual) | C11: PAC-2024-001/013/029/035/036/037/038/040/041/042/049/101/115/116 | D11: 675840 | E11: [Múltiples proveedores — procesos en ejecución] | F11: Adjudicado | G11: https://www.compraspublicas.gob.ec/ProcesoContratacion/compras/PC/buscarProceso.cpe?sg=PAC2024GADMC | H11: =IF(AND(C11<>"",F11="Adjudicado"),1,IF(C11<>"",0.5,0)) -> 1 | I11: =IF(AND(D11>0,D11>H04_S2_PLANIFICACIÓN_PDOT!G10),"⚠️ Monto supera planificación PDOT","✅ OK") -> ✅ OK
A12: =H04_S2_PLANIFICACIÓN_PDOT!A11 -> AH-I-N-01 | B12: =H04_S2_PLANIFICACIÓN_PDOT!B11 -> Gestión integral desechos sólidos: 20,118→23,086 Tn/año; relleno sanitario; capacidad disposición 0%→20% | C12: DEA-MONTEHOGAR-2024 | D12: 0 | E12: EP Montehogar — RUC adscrito | F12: DEA | G12: https://www.compraspublicas.gob.ec/ProcesoContratacion/compras/PC/buscarProceso.cpe?sg=PAC2024GADMC | H12: =IF(AND(C12<>"",F12="Adjudicado"),1,IF(C12<>"",0.5,0)) -> 0.5 | I12: =IF(AND(D12>0,D12>H04_S2_PLANIFICACIÓN_PDOT!G11),"⚠️ Monto supera planificación PDOT","✅ OK") -> ✅ OK
A13: =H04_S2_PLANIFICACIÓN_PDOT!A12 -> SC-L-G-01 | B13: =H04_S2_PLANIFICACIÓN_PDOT!B12 -> Alcantarillado sanitario: cobertura 19.77%→24.32%; PTAR 0%→75%; estaciones bombeo 36%→72% | C13: PAC-2024-125/147/156/157/159 | D13: 299271 | E13: [SPD — múltiples proveedores] | F13: En_proceso | G13: https://www.compraspublicas.gob.ec/ProcesoContratacion/compras/PC/buscarProceso.cpe?sg=PAC2024GADMC | H13: =IF(AND(C13<>"",F13="Adjudicado"),1,IF(C13<>"",0.5,0)) -> 0.5 | I13: =IF(AND(D13>0,D13>H04_S2_PLANIFICACIÓN_PDOT!G12),"⚠️ Monto supera planificación PDOT","✅ OK") -> ✅ OK
A14: =H04_S2_PLANIFICACIÓN_PDOT!A13 -> AH-I-X-04 | B14: =H04_S2_PLANIFICACIÓN_PDOT!B13 -> Modernización recursos administrativos: parque automotor, tecnología e infraestructura municipal | C14: PAC-2024-008/051/058/060/061/065/095/098/109/118/119 | D14: 422356 | E14: [Múltiples proveedores — procesos en ejecución] | F14: Adjudicado | G14: https://www.compraspublicas.gob.ec/ProcesoContratacion/compras/PC/buscarProceso.cpe?sg=PAC2024GADMC | H14: =IF(AND(C14<>"",F14="Adjudicado"),1,IF(C14<>"",0.5,0)) -> 1 | I14: =IF(AND(D14>0,D14>H04_S2_PLANIFICACIÓN_PDOT!G13),"⚠️ Monto supera planificación PDOT","✅ OK") -> ✅ OK
A15: =H04_S2_PLANIFICACIÓN_PDOT!A14 -> PI-I-G-01 | B15: =H04_S2_PLANIFICACIÓN_PDOT!B14 -> Equipamientos públicos: terminal terrestre, mercado, estación bomberil, centro salud tipo C, mantenimiento espacios recreativos | C15: PAC-2024-003/005/006/007/009/014/021/022/024/047/072/073/075/076/089/097/102/103/104/105/106/107/108/117/139/155/165/166 | D15: 2183216 | E15: [Múltiples proveedores — procesos en ejecución] | F15: Adjudicado | G15: https://www.compraspublicas.gob.ec/ProcesoContratacion/compras/PC/buscarProceso.cpe?sg=PAC2024GADMC | H15: =IF(AND(C15<>"",F15="Adjudicado"),1,IF(C15<>"",0.5,0)) -> 1 | I15: =IF(AND(D15>0,D15>H04_S2_PLANIFICACIÓN_PDOT!G14),"⚠️ Monto supera planificación PDOT","✅ OK") -> ⚠️ Monto supera planificación PDOT
A16: =H04_S2_PLANIFICACIÓN_PDOT!A15 -> AH-C-X-01 | B16: =H04_S2_PLANIFICACIÓN_PDOT!B15 -> Protección derechos sociales: atenciones grupos prioritarios 943→1,649 (+15%/año); CDI; adultos mayores; violencia de género | C16: PAC-2024-010/019/045/059/064/091/099/128/129/130/149/153 | D16: 558105 | E16: [Múltiples proveedores — procesos en ejecución] | F16: Adjudicado | G16: https://www.compraspublicas.gob.ec/ProcesoContratacion/compras/PC/buscarProceso.cpe?sg=PAC2024GADMC | H16: =IF(AND(C16<>"",F16="Adjudicado"),1,IF(C16<>"",0.5,0)) -> 1 | I16: =IF(AND(D16>0,D16>H04_S2_PLANIFICACIÓN_PDOT!G15),"⚠️ Monto supera planificación PDOT","✅ OK") -> ⚠️ Monto supera planificación PDOT
A17: =H04_S2_PLANIFICACIÓN_PDOT!A16 -> AH-C-X-02 | B17: =H04_S2_PLANIFICACIÓN_PDOT!B16 -> Sistema información territorial: catastro urbano-rural 19.52%→80%; 12 procesos sistematizados; 37 trámites en línea | C17: PAC-2024-030/043/044/063/067/111/150 | D17: 625859 | E17: [Múltiples proveedores — procesos en ejecución] | F17: Adjudicado | G17: https://www.compraspublicas.gob.ec/ProcesoContratacion/compras/PC/buscarProceso.cpe?sg=PAC2024GADMC | H17: =IF(AND(C17<>"",F17="Adjudicado"),1,IF(C17<>"",0.5,0)) -> 1 | I17: =IF(AND(D17>0,D17>H04_S2_PLANIFICACIÓN_PDOT!G16),"⚠️ Monto supera planificación PDOT","✅ OK") -> ⚠️ Monto supera planificación PDOT
A18: =H04_S2_PLANIFICACIÓN_PDOT!A17 -> SC-I-N-03 | B18: =H04_S2_PLANIFICACIÓN_PDOT!B17 -> Participación ciudadana: 50→100 Unidades Territoriales participativas; 2→4 instancias efectivas (COPFP Art.115) | C18: PAC-2024-079/081/083/084/124/135/141 | D18: 37000 | E18: [SPD — múltiples proveedores] | F18: En_proceso | G18: https://www.compraspublicas.gob.ec/ProcesoContratacion/compras/PC/buscarProceso.cpe?sg=PAC2024GADMC | H18: =IF(AND(C18<>"",F18="Adjudicado"),1,IF(C18<>"",0.5,0)) -> 0.5 | I18: =IF(AND(D18>0,D18>H04_S2_PLANIFICACIÓN_PDOT!G17),"⚠️ Monto supera planificación PDOT","✅ OK") -> ⚠️ Monto supera planificación PDOT
A19: =H04_S2_PLANIFICACIÓN_PDOT!A18 -> FA-I-X-01 | B19: =H04_S2_PLANIFICACIÓN_PDOT!B18 -> Gestión del riesgo: reducir 10% infraestructura susceptible (3,655→2,398 unidades); alerta temprana climática | C19: PAC-2024-018/053 | D19: 78500 | E19: [Por adjudicar — PAC publicado] | F19: Adjudicado | G19: https://www.compraspublicas.gob.ec/ProcesoContratacion/compras/PC/buscarProceso.cpe?sg=PAC2024GADMC | H19: =IF(AND(C19<>"",F19="Adjudicado"),1,IF(C19<>"",0.5,0)) -> 1 | I19: =IF(AND(D19>0,D19>H04_S2_PLANIFICACIÓN_PDOT!G18),"⚠️ Monto supera planificación PDOT","✅ OK") -> ✅ OK
A20: =H04_S2_PLANIFICACIÓN_PDOT!A19 -> FA-C-X-01 | B20: =H04_S2_PLANIFICACIÓN_PDOT!B19 -> Áreas verdes y parques: IVU 10.94→17.32 m²/hab; parques inter-barriales; recuperación manglar perfil costero | C20: DEA-ASEO-EP-2024 | D20: 5000 | E20: EP Aseo Montecristi — RUC adscrito | F20: DEA | G20: https://www.compraspublicas.gob.ec/ProcesoContratacion/compras/PC/buscarProceso.cpe?sg=PAC2024GADMC | H20: =IF(AND(C20<>"",F20="Adjudicado"),1,IF(C20<>"",0.5,0)) -> 0.5 | I20: =IF(AND(D20>0,D20>H04_S2_PLANIFICACIÓN_PDOT!G19),"⚠️ Monto supera planificación PDOT","✅ OK") -> ✅ OK
A21: =H04_S2_PLANIFICACIÓN_PDOT!A20 -> FA-I-X-02 | B21: =H04_S2_PLANIFICACIÓN_PDOT!B20 -> Índice equipamiento urbano CUP 9.96→10.73 m²/hab; recolección desechos 91.95%→97.95%; 77.83→81.07 km/día barrido | C21: PAC-2024-013/046/055/110/131 | D21: 37600 | E21: [Por adjudicar — PAC publicado] | F21: Adjudicado | G21: https://www.compraspublicas.gob.ec/ProcesoContratacion/compras/PC/buscarProceso.cpe?sg=PAC2024GADMC | H21: =IF(AND(C21<>"",F21="Adjudicado"),1,IF(C21<>"",0.5,0)) -> 1 | I21: =IF(AND(D21>0,D21>H04_S2_PLANIFICACIÓN_PDOT!G20),"⚠️ Monto supera planificación PDOT","✅ OK") -> ✅ OK
A22: =H04_S2_PLANIFICACIÓN_PDOT!A21 -> FA-L-N-01 | B22: =H04_S2_PLANIFICACIÓN_PDOT!B21 -> Inventario patrimonial 100% al 2026; 8,000→10,000 participantes eventos culturales; Museo del Sombrero | C22: PAC-2024-122 | D22: 5000 | E22: [SPD — proveedor único] | F22: En_proceso | G22: https://www.compraspublicas.gob.ec/ProcesoContratacion/compras/PC/buscarProceso.cpe?sg=PAC2024GADMC | H22: =IF(AND(C22<>"",F22="Adjudicado"),1,IF(C22<>"",0.5,0)) -> 0.5 | I22: =IF(AND(D22>0,D22>H04_S2_PLANIFICACIÓN_PDOT!G21),"⚠️ Monto supera planificación PDOT","✅ OK") -> ✅ OK
... A26: =H04_S2_PLANIFICACIÓN_PDOT!A25 -> EP-L-X-01 | B26: =H04_S2_PLANIFICACIÓN_PDOT!B25 -> Fortalecimiento productivo: beneficiarios artesanos, mipymes, emprendedores, huertos comunitarios y cadenas de valor | C26: PAC-2024-120/121 | D26: 163400 | E26: [Por adjudicar — PAC publicado] | F26: Adjudicado | G26: https://www.compraspublicas.gob.ec/ProcesoContratacion/compras/PC/buscarProceso.cpe?sg=PAC2024GADMC | H26: =IF(AND(C26<>"",F26="Adjudicado"),1,IF(C26<>"",0.5,0)) -> 1 | I26: =IF(AND(D26>0,D26>H04_S2_PLANIFICACIÓN_PDOT!G25),"⚠️ Monto supera planificación PDOT","✅ OK") -> ⚠️ Monto supera planificación PDOT

Sheet H07_S5_FINANCIERO_eSIGEF
A1: ⚠️ SIMULACIÓN TÉCNICA — CÉDULA 2024: Datos simulados a partir del PAC 2024 oficial y POA 2024 del GAD Montecristi. Portal eSIGEF no es de acceso público. Actualizar con cédula real cuando el GAD autorice el acceso. Metodología: tasas de ejecución basadas en estándares GADs similares Ecuador. Ref. Memorandum 0511-CNVC-DF-GADMCM-2026 | B1: ⬅️ ÍNDICE GENERAL | C1: ="ICPI: "&TEXT(H12_MOTOR_ICPI_CANÓNICO!B28,"0,0")&"%" -> ICPI: 72,9% | D1: H07 — S5 eSIGEF | E1: =TEXT(TODAY(),"DD/MM/YYYY") -> 05/04/2026
A2: S5 — SILO FINANCIERO (eSIGEF/MEF)
A3: Ejecución presupuestaria con devengado certificado en el sistema nacional del MEF. Registra el momento en que el bien o servicio es efectivamente recibido.
A4: Fundamentación: COPFP Arts.115-117 + Acuerdo 067 MEF
A6: ID_Meta | B6: Descripción_Meta | C6: Partida_Presupuestaria | D6: Grupo_Presup | E6: Codificado | F6: Devengado | G6: T_i (Tasa Ejec.) | H6: V_eSIGEF | I6: Flag_SAT_IV
A7: =H04_S2_PLANIFICACIÓN_PDOT!A6 -> SC-I-N-01 | B7: =H04_S2_PLANIFICACIÓN_PDOT!B6 -> Agua potable: cobertura 39.25%→42.38%; calidad 100% INEN 1108; infraestructura BUENA 22.74%→41.64% | C7: 73.08 | D7: 73 | E7: 45000 | F7: =E7*0.95 -> 42750 | G7: =IF(E7>0,F7/E7,0) -> 0.95 | H7: =IF(F7>0,1,IF(E7>0,0.5,0)) -> 1 | I7: =IF(AND(OR(D7=71,D7=73,D7=78),F7>0,H01_PARÁMETROS!B34="SÍ"),"⚠️ SAT-IV — Meta social en período restricción fiscal","✅ OK") -> ✅ OK
